Workbook

Sheet هيكل الآيبان
A1: هيكل رقم الآيبان السعودي (ISO 13616) — 24 خانة
A2: SA + خانتا تدقيق + رمز البنك (خانتان) + رقم الحساب (18 خانة). المرجع: سجل SWIFT للآيبان، صيغة SA2!n2!n18!c
A4: الجزء | B4: عدد الخانات | C4: المواقع | D4: مثال | E4: الوصف
A5: رمز الدولة | B5: 2 | C5: 1–2 | D5: SA | E5: يرمز للمملكة العربية السعودية (ISO 3166). ثابت لكل الحسابات السعودية.
A6: حقل التدقيق | B6: 2 | C6: 3–4 | D6: 03 | E6: رقمان يُحسبان بخوارزمية MOD-97 من رمز البنك ورقم الحساب معاً، فهما يختلفان من حساب لآخر حتى داخل البنك نفسه، ولا يوجد حقل تدقيق ثابت للبنك. وظيفتهما كشف أخطاء الإدخال (أي خطأ في خانة واحدة أو تبديل خانتين متجاورتين).
A7: رمز البنك | B7: 2 | C7: 5–6 | D7: 80 | E7: رقم ثنائي تصدره ساما لكل بنك: 80 مصرف الراجحي، 10 البنك الأهلي السعودي، 20 بنك الرياض، 55 البنك السعودي الفرنسي. الجدول الكامل في ورقة «رموز البنوك».
A8: رقم الحساب | B8: 18 | C8: 7–24 | D8: 000000608010167519 | E8: رقم الحساب لدى البنك، يُكمَّل بأصفار على اليسار حتى 18 خانة (يسمح المعيار بحروف وأرقام).
A9: الآيبان كاملاً | B9: 24 | C9: 1–24 | D9: SA03 8000 0000 6080 1016 7519 | E9: يُكتب إلكترونياً بلا مسافات، ويُطبع في مجموعات من 4 خانات.
A11: تصحيح للأمثلة الواردة في الطلب: الرمز 20 هو بنك الرياض (وليس الراجحي)، و55 هو البنك السعودي الفرنسي (وليس الأهلي). الراجحي = 80، الأهلي = 10.

Sheet رموز البنوك
A1: رموز البنوك العاملة في المملكة العربية السعودية في رقم الآيبان
A2: حقل التدقيق ليس صفة للبنك بل للحساب: العمود J مدخل (رقم حساب من 18 خانة)، والعمودان K و L يحسبان حقل التدقيق والآيبان آلياً. القيمة الافتراضية في J هي حساب المثال في سجل SWIFT، مكررة لكل بنك لإظهار تغيّر خانتي التدقيق بتغيّر رمز البنك.
A4: # | B4: رمز البنك | C4: اسم البنك | D4: Bank name | E4: رمز SWIFT / BIC | F4: توثيق SWIFT | G4: الحالة | H4: ملاحظة | I4: الآيبان يبدأ بـ | J4: رقم الحساب (18 خانة) — مدخل | K4: حقل التدقيق (محسوب) | L4: الآيبان الكامل (محسوب) | M4: التحقق MOD-97 | N4: سلسلة الحساب (مساعد)
A5: 1 | B5: 05 | C5: مصرف الإنماء | D5: Alinma Bank | E5: INMASARI | F5: مؤكد | G5: نشط | I5: ="SA"&"xx"&B5 -> SAxx05 | J5: 000000608010167519 | K5: =IF(LEN(J5)<>18,"طول خاطئ",TEXT(98-MOD(VALUE(MOD(VALUE(MOD(VALUE(MOD(VALUE(MID(N5,1,9)),97)&MID(N5,10,7)),97)&MID(N5,17,7)),97)&MID(N5,24,7)),97),"00")) -> 02 | L5: =IF(LEN(J5)<>18,"","SA"&K5&" "&MID(B5&J5,1,4)&" "&MID(B5&J5,5,4)&" "&MID(B5&J5,9,4)&" "&MID(B5&J5,13,4)&" "&MID(B5&J5,17,4)) -> SA02 0500 0000 6080 1016 7519 | M5: =IF(LEN(J5)<>18,"",IF(MOD(VALUE(MOD(VALUE(MOD(VALUE(MOD(VALUE(MID((B5&J5&"2810"&K5),1,9)),97)&MID((B5&J5&"2810"&K5),10,7)),97)&MID((B5&J5&"2810"&K5),17,7)),97)&MID((B5&J5&"2810"&K5),24,7)),97)=1,"صحيح ✓","خطأ")) -> صحيح ✓ | N5: =B5&J5&"281000" -> 05000000608010167519281000
A6: 2 | B6: 10 | C6: البنك الأهلي السعودي | D6: Saudi National Bank (SNB) | E6: NCBKSAJE | F6: مؤكد | G6: نشط | H6: يشمل حسابات سامبا المنقولة بعد الاندماج 2021 | I6: ="SA"&"xx"&B6 -> SAxx10 | J6: 000000608010167519 | K6: =IF(LEN(J6)<>18,"طول خاطئ",TEXT(98-MOD(VALUE(MOD(VALUE(MOD(VALUE(MOD(VALUE(MID(N6,1,9)),97)&MID(N6,10,7)),97)&MID(N6,17,7)),97)&MID(N6,24,7)),97),"00")) -> 15 | L6: =IF(LEN(J6)<>18,"","SA"&K6&" "&MID(B6&J6,1,4)&" "&MID(B6&J6,5,4)&" "&MID(B6&J6,9,4)&" "&MID(B6&J6,13,4)&" "&MID(B6&J6,17,4)) -> SA15 1000 0000 6080 1016 7519 | M6: =IF(LEN(J6)<>18,"",IF(MOD(VALUE(MOD(VALUE(MOD(VALUE(MOD(VALUE(MID((B6&J6&"2810"&K6),1,9)),97)&MID((B6&J6&"2810"&K6),10,7)),97)&MID((B6&J6&"2810"&K6),17,7)),97)&MID((B6&J6&"2810"&K6),24,7)),97)=1,"صحيح ✓","خطأ")) -> صحيح ✓ | N6: =B6&J6&"281000" -> 10000000608010167519281000
A7: 3 | B7: 15 | C7: بنك البلاد | D7: Bank Albilad | E7: ALBISARI | F7: مؤكد | G7: نشط | I7: ="SA"&"xx"&B7 -> SAxx15 | J7: 000000608010167519 | K7: =IF(LEN(J7)<>18,"طول خاطئ",TEXT(98-MOD(VALUE(MOD(VALUE(MOD(VALUE(MOD(VALUE(MID(N7,1,9)),97)&MID(N7,10,7)),97)&MID(N7,17,7)),97)&MID(N7,24,7)),97),"00")) -> 28 | L7: =IF(LEN(J7)<>18,"","SA"&K7&" "&MID(B7&J7,1,4)&" "&MID(B7&J7,5,4)&" "&MID(B7&J7,9,4)&" "&MID(B7&J7,13,4)&" "&MID(B7&J7,17,4)) -> SA28 1500 0000 6080 1016 7519 | M7: =IF(LEN(J7)<>18,"",IF(MOD(VALUE(MOD(VALUE(MOD(VALUE(MOD(VALUE(MID((B7&J7&"2810"&K7),1,9)),97)&MID((B7&J7&"2810"&K7),10,7)),97)&MID((B7&J7&"2810"&K7),17,7)),97)&MID((B7&J7&"2810"&K7),24,7)),97)=1,"صحيح ✓","خطأ")) -> صحيح ✓ | N7: =B7&J7&"281000" -> 15000000608010167519281000
A8: 4 | B8: 20 | C8: بنك الرياض | D8: Riyad Bank | E8: RIBLSARI | F8: مؤكد | G8: نشط | I8: ="SA"&"xx"&B8 -> SAxx20 | J8: 000000608010167519 | K8: =IF(LEN(J8)<>18,"طول خاطئ",TEXT(98-MOD(VALUE(MOD(VALUE(MOD(VALUE(MOD(VALUE(MID(N8,1,9)),97)&MID(N8,10,7)),97)&MID(N8,17,7)),97)&MID(N8,24,7)),97),"00")) -> 41 | L8: =IF(LEN(J8)<>18,"","SA"&K8&" "&MID(B8&J8,1,4)&" "&MID(B8&J8,5,4)&" "&MID(B8&J8,9,4)&" "&MID(B8&J8,13,4)&" "&MID(B8&J8,17,4)) -> SA41 2000 0000 6080 1016 7519 | M8: =IF(LEN(J8)<>18,"",IF(MOD(VALUE(MOD(VALUE(MOD(VALUE(MOD(VALUE(MID((B8&J8&"2810"&K8),1,9)),97)&MID((B8&J8&"2810"&K8),10,7)),97)&MID((B8&J8&"2810"&K8),17,7)),97)&MID((B8&J8&"2810"&K8),24,7)),97)=1,"صحيح ✓","خطأ")) -> صحيح ✓ | N8: =B8&J8&"281000" -> 20000000608010167519281000
A9: 5 | B9: 30 | C9: البنك العربي الوطني | D9: Arab National Bank | E9: ARNBSARI | F9: مؤكد | G9: نشط | I9: ="SA"&"xx"&B9 -> SAxx30 | J9: 000000608010167519 | K9: =IF(LEN(J9)<>18,"طول خاطئ",TEXT(98-MOD(VALUE(MOD(VALUE(MOD(VALUE(MOD(VALUE(MID(N9,1,9)),97)&MID(N9,10,7)),97)&MID(N9,17,7)),97)&MID(N9,24,7)),97),"00")) -> 67 | L9: =IF(LEN(J9)<>18,"","SA"&K9&" "&MID(B9&J9,1,4)&" "&MID(B9&J9,5,4)&" "&MID(B9&J9,9,4)&" "&MID(B9&J9,13,4)&" "&MID(B9&J9,17,4)) -> SA67 3000 0000 6080 1016 7519 | M9: =IF(LEN(J9)<>18,"",IF(MOD(VALUE(MOD(VALUE(MOD(VALUE(MOD(VALUE(MID((B9&J9&"2810"&K9),1,9)),97)&MID((B9&J9&"2810"&K9),10,7)),97)&MID((B9&J9&"2810"&K9),17,7)),97)&MID((B9&J9&"2810"&K9),24,7)),97)=1,"صحيح ✓","خطأ")) -> صحيح ✓ | N9: =B9&J9&"281000" -> 30000000608010167519281000
A10: 6 | B10: 36 | C10: بنك دال ثلاثمائة وستون (D360) | D10: D360 Bank | E10: DBAKSARI | F10: مؤكد | G10: بنك رقمي | H10: مؤكد بآيبان فعلي لحساب في البنك قدّمه المستخدم (SA83 3603 …) يجتاز MOD-97، ويتفق مع الملف الاسترشادي | I10: ="SA"&"xx"&B10 -> SAxx36 | J10: 000000608010167519 | K10: =IF(LEN(J10)<>18,"طول خاطئ",TEXT(98-MOD(VALUE(MOD(VALUE(MOD(VALUE(MOD(VALUE(MID(N10,1,9)),97)&MID(N10,10,7)),97)&MID(N10,17,7)),97)&MID(N10,24,7)),97),"00")) -> 05 | L10: =IF(LEN(J10)<>18,"","SA"&K10&" "&MID(B10&J10,1,4)&" "&MID(B10&J10,5,4)&" "&MID(B10&J10,9,4)&" "&MID(B10&J10,13,4)&" "&MID(B10&J10,17,4)) -> SA05 3600 0000 6080 1016 7519 | M10: =IF(LEN(J10)<>18,"",IF(MOD(VALUE(MOD(VALUE(MOD(VALUE(MOD(VALUE(MID((B10&J10&"2810"&K10),1,9)),97)&MID((B10&J10&"2810"&K10),10,7)),97)&MID((B10&J10&"2810"&K10),17,7)),97)&MID((B10&J10&"2810"&K10),24,7)),97)=1,"صحيح ✓","خطأ")) -> صحيح ✓ | N10: =B10&J10&"281000" -> 36000000608010167519281000
A11: 7 | B11: 40 | C11: مجموعة سامبا المالية | D11: Samba Financial Group | E11: SAMBSARI | F11: غير مؤكد (بنك مدمج) | G11: مدمج (تاريخي) | H11: اندمج في البنك الأهلي السعودي 2021؛ قد تبقى آيبانات قديمة متداولة | I11: ="SA"&"xx"&B11 -> SAxx40 | J11: 000000608010167519 | K11: =IF(LEN(J11)<>18,"طول خاطئ",TEXT(98-MOD(VALUE(MOD(VALUE(MOD(VALUE(MOD(VALUE(MID(N11,1,9)),97)&MID(N11,10,7)),97)&MID(N11,17,7)),97)&MID(N11,24,7)),97),"00")) -> 93 | L11: =IF(LEN(J11)<>18,"","SA"&K11&" "&MID(B11&J11,1,4)&" "&MID(B11&J11,5,4)&" "&MID(B11&J11,9,4)&" "&MID(B11&J11,13,4)&" "&MID(B11&J11,17,4)) -> SA93 4000 0000 6080 1016 7519 | M11: =IF(LEN(J11)<>18,"",IF(MOD(VALUE(MOD(VALUE(MOD(VALUE(MOD(VALUE(MID((B11&J11&"2810"&K11),1,9)),97)&MID((B11&J11&"2810"&K11),10,7)),97)&MID((B11&J11&"2810"&K11),17,7)),97)&MID((B11&J11&"2810"&K11),24,7)),97)=1,"صحيح ✓","خطأ")) -> صحيح ✓ | N11: =B11&J11&"281000" -> 40000000608010167519281000
A12: 8 | B12: 45 | C12: البنك السعودي الأول (ساب) | D12: Saudi Awwal Bank (SAB, formerly SABB) | E12: SABBSARI | F12: مؤكد | G12: نشط | I12: ="SA"&"xx"&B12 -> SAxx45 | J12: 000000608010167519 | K12: =IF(LEN(J12)<>18,"طول خاطئ",TEXT(98-MOD(VALUE(MOD(VALUE(MOD(VALUE(MOD(VALUE(MID(N12,1,9)),97)&MID(N12,10,7)),97)&MID(N12,17,7)),97)&MID(N12,24,7)),97),"00")) -> 09 | L12: =IF(LEN(J12)<>18,"","SA"&K12&" "&MID(B12&J12,1,4)&" "&MID(B12&J12,5,4)&" "&MID(B12&J12,9,4)&" "&MID(B12&J12,13,4)&" "&MID(B12&J12,17,4)) -> SA09 4500 0000 6080 1016 7519 | M12: =IF(LEN(J12)<>18,"",IF(MOD(VALUE(MOD(VALUE(MOD(VALUE(MOD(VALUE(MID((B12&J12&"2810"&K12),1,9)),97)&MID((B12&J12&"2810"&K12),10,7)),97)&MID((B12&J12&"2810"&K12),17,7)),97)&MID((B12&J12&"2810"&K12),24,7)),97)=1,"صحيح ✓","خطأ")) -> صحيح ✓ | N12: =B12&J12&"281000" -> 45000000608010167519281000
A13: 9 | B13: 50 | C13: البنك الأول | D13: Alawwal Bank | E13: AAALSARI | F13: مصدر واحد (بنك مدمج) | G13: مدمج (تاريخي) | H13: اندمج في ساب 2019؛ قد تبقى آيبانات قديمة متداولة | I13: ="SA"&"xx"&B13 -> SAxx50 | J13: 000000608010167519 | K13: =IF(LEN(J13)<>18,"طول خاطئ",TEXT(98-MOD(VALUE(MOD(VALUE(MOD(VALUE(MOD(VALUE(MID(N13,1,9)),97)&MID(N13,10,7)),97)&MID(N13,17,7)),97)&MID(N13,24,7)),97),"00")) -> 22 | L13: =IF(LEN(J13)<>18,"","SA"&K13&" "&MID(B13&J13,1,4)&" "&MID(B13&J13,5,4)&" "&MID(B13&J13,9,4)&" "&MID(B13&J13,13,4)&" "&MID(B13&J13,17,4)) -> SA22 5000 0000 6080 1016 7519 | M13: =IF(LEN(J13)<>18,"",IF(MOD(VALUE(MOD(VALUE(MOD(VALUE(MOD(VALUE(MID((B13&J13&"2810"&K13),1,9)),97)&MID((B13&J13&"2810"&K13),10,7)),97)&MID((B13&J13&"2810"&K13),17,7)),97)&MID((B13&J13&"2810"&K13),24,7)),97)=1,"صحيح ✓","خطأ")) -> صحيح ✓ | N13: =B13&J13&"281000" -> 50000000608010167519281000
A14: 10 | B14: 55 | C14: البنك السعودي الفرنسي | D14: Banque Saudi Fransi | E14: BSFRSARI | F14: مؤكد | G14: نشط | I14: ="SA"&"xx"&B14 -> SAxx55 | J14: 000000608010167519 | K14: =IF(LEN(J14)<>18,"طول خاطئ",TEXT(98-MOD(VALUE(MOD(VALUE(MOD(VALUE(MOD(VALUE(MID(N14,1,9)),97)&MID(N14,10,7)),97)&MID(N14,17,7)),97)&MID(N14,24,7)),97),"00")) -> 35 | L14: =IF(LEN(J14)<>18,"","SA"&K14&" "&MID(B14&J14,1,4)&" "&MID(B14&J14,5,4)&" "&MID(B14&J14,9,4)&" "&MID(B14&J14,13,4)&" "&MID(B14&J14,17,4)) -> SA35 5500 0000 6080 1016 7519 | M14: =IF(LEN(J14)<>18,"",IF(MOD(VALUE(MOD(VALUE(MOD(VALUE(MOD(VALUE(MID((B14&J14&"2810"&K14),1,9)),97)&MID((B14&J14&"2810"&K14),10,7)),97)&MID((B14&J14&"2810"&K14),17,7)),97)&MID((B14&J14&"2810"&K14),24,7)),97)=1,"صحيح ✓","خطأ")) -> صحيح ✓ | N14: =B14&J14&"281000" -> 55000000608010167519281000
A15: 11 | B15: 60 | C15: بنك الجزيرة | D15: Bank AlJazira | E15: BJAZSAJE | F15: مؤكد | G15: نشط | I15: ="SA"&"xx"&B15 -> SAxx60 | J15: 000000608010167519 | K15: =IF(LEN(J15)<>18,"طول خاطئ",TEXT(98-MOD(VALUE(MOD(VALUE(MOD(VALUE(MOD(VALUE(MID(N15,1,9)),97)&MID(N15,10,7)),97)&MID(N15,17,7)),97)&MID(N15,24,7)),97),"00")) -> 48 | L15: =IF(LEN(J15)<>18,"","SA"&K15&" "&MID(B15&J15,1,4)&" "&MID(B15&J15,5,4)&" "&MID(B15&J15,9,4)&" "&MID(B15&J15,13,4)&" "&MID(B15&J15,17,4)) -> SA48 6000 0000 6080 1016 7519 | M15: =IF(LEN(J15)<>18,"",IF(MOD(VALUE(MOD(VALUE(MOD(VALUE(MOD(VALUE(MID((B15&J15&"2810"&K15),1,9)),97)&MID((B15&J15&"2810"&K15),10,7)),97)&MID((B15&J15&"2810"&K15),17,7)),97)&MID((B15&J15&"2810"&K15),24,7)),97)=1,"صحيح ✓","خطأ")) -> صحيح ✓ | N15: =B15&J15&"281000" -> 60000000608010167519281000
A16: 12 | B16: 65 | C16: البنك السعودي للاستثمار | D16: The Saudi Investment Bank | E16: SIBCSARI | F16: مؤكد | G16: نشط | I16: ="SA"&"xx"&B16 -> SAxx65 | J16: 000000608010167519 | K16: =IF(LEN(J16)<>18,"طول خاطئ",TEXT(98-MOD(VALUE(MOD(VALUE(MOD(VALUE(MOD(VALUE(MID(N16,1,9)),97)&MID(N16,10,7)),97)&MID(N16,17,7)),97)&MID(N16,24,7)),97),"00")) -> 61 | L16: =IF(LEN(J16)<>18,"","SA"&K16&" "&MID(B16&J16,1,4)&" "&MID(B16&J16,5,4)&" "&MID(B16&J16,9,4)&" "&MID(B16&J16,13,4)&" "&MID(B16&J16,17,4)) -> SA61 6500 0000 6080 1016 7519 | M16: =IF(LEN(J16)<>18,"",IF(MOD(VALUE(MOD(VALUE(MOD(VALUE(MOD(VALUE(MID((B16&J16&"2810"&K16),1,9)),97)&MID((B16&J16&"2810"&K16),10,7)),97)&MID((B16&J16&"2810"&K16),17,7)),97)&MID((B16&J16&"2810"&K16),24,7)),97)=1,"صحيح ✓","خطأ")) -> صحيح ✓ | N16: =B16&J16&"281000" -> 65000000608010167519281000
A17: 13 | B17: 71 | C17: بنك البحرين الوطني (فرع السعودية) | D17: National Bank of Bahrain | E17: NBOBSARI | F17: مصدر واحد | G17: فرع بنك أجنبي | I17: ="SA"&"xx"&B17 -> SAxx71 | J17: 000000608010167519 | K17: =IF(LEN(J17)<>18,"طول خاطئ",TEXT(98-MOD(VALUE(MOD(VALUE(MOD(VALUE(MOD(VALUE(MID(N17,1,9)),97)&MID(N17,10,7)),97)&MID(N17,17,7)),97)&MID(N17,24,7)),97),"00")) -> 96 | L17: =IF(LEN(J17)<>18,"","SA"&K17&" "&MID(B17&J17,1,4)&" "&MID(B17&J17,5,4)&" "&MID(B17&J17,9,4)&" "&MID(B17&J17,13,4)&" "&MID(B17&J17,17,4)) -> SA96 7100 0000 6080 1016 7519 | M17: =IF(LEN(J17)<>18,"",IF(MOD(VALUE(MOD(VALUE(MOD(VALUE(MOD(VALUE(MID((B17&J17&"2810"&K17),1,9)),97)&MID((B17&J17&"2810"&K17),10,7)),97)&MID((B17&J17&"2810"&K17),17,7)),97)&MID((B17&J17&"2810"&K17),24,7)),97)=1,"صحيح ✓","خطأ")) -> صحيح ✓ | N17: =B17&J17&"281000" -> 71000000608010167519281000
A18: 14 | B18: 73 | C18: بنك أبوظبي الأول (فرع السعودية) | D18: First Abu Dhabi Bank (FAB) | E18: FABMSARI | F18: مصدر واحد + الملف الاسترشادي | G18: فرع بنك أجنبي | H18: مؤكد بآيبان فعلي لحساب في البنك قدّمه المستخدم (SA63 7300 …) يجتاز MOD-97، ويتفق مع الملف الاسترشادي | I18: ="SA"&"xx"&B18 -> SAxx73 | J18: 000000608010167519 | K18: =IF(LEN(J18)<>18,"طول خاطئ",TEXT(98-MOD(VALUE(MOD(VALUE(MOD(VALUE(MOD(VALUE(MID(N18,1,9)),97)&MID(N18,10,7)),97)&MID(N18,17,7)),97)&MID(N18,24,7)),97),"00")) -> 43 | L18: =IF(LEN(J18)<>18,"","SA"&K18&" "&MID(B18&J18,1,4)&" "&MID(B18&J18,5,4)&" "&MID(B18&J18,9,4)&" "&MID(B18&J18,13,4)&" "&MID(B18&J18,17,4)) -> SA43 7300 0000 6080 1016 7519 | M18: =IF(LEN(J18)<>18,"",IF(MOD(VALUE(MOD(VALUE(MOD(VALUE(MOD(VALUE(MID((B18&J18&"2810"&K18),1,9)),97)&MID((B18&J18&"2810"&K18),10,7)),97)&MID((B18&J18&"2810"&K18),17,7)),97)&MID((B18&J18&"2810"&K18),24,7)),97)=1,"صحيح ✓","خطأ")) -> صحيح ✓ | N18: =B18&J18&"281000" -> 73000000608010167519281000
A19: 15 | B19: 75 | C19: بنك الكويت الوطني (فرع السعودية) | D19: National Bank of Kuwait | E19: NBOKSAJE | F19: مصدر واحد + الملف الاسترشادي | G19: فرع بنك أجنبي | I19: ="SA"&"xx"&B19 -> SAxx75 | J19: 000000608010167519 | K19: =IF(LEN(J19)<>18,"طول خاطئ",TEXT(98-MOD(VALUE(MOD(VALUE(MOD(VALUE(MOD(VALUE(MID(N19,1,9)),97)&MID(N19,10,7)),97)&MID(N19,17,7)),97)&MID(N19,24,7)),97),"00")) -> 87 | L19: =IF(LEN(J19)<>18,"","SA"&K19&" "&MID(B19&J19,1,4)&" "&MID(B19&J19,5,4)&" "&MID(B19&J19,9,4)&" "&MID(B19&J19,13,4)&" "&MID(B19&J19,17,4)) -> SA87 7500 0000 6080 1016 7519 | M19: =IF(LEN(J19)<>18,"",IF(MOD(VALUE(MOD(VALUE(MOD(VALUE(MOD(VALUE(MID((B19&J19&"2810"&K19),1,9)),97)&MID((B19&J19&"2810"&K19),10,7)),97)&MID((B19&J19&"2810"&K19),17,7)),97)&MID((B19&J19&"2810"&K19),24,7)),97)=1,"صحيح ✓","خطأ")) -> صحيح ✓ | N19: =B19&J19&"281000" -> 75000000608010167519281000
A20: 16 | B20: 76 | C20: بنك مسقط (فرع السعودية) | D20: Bank Muscat | E20: BMUSSARI | F20: مصدر واحد | G20: فرع بنك أجنبي | I20: ="SA"&"xx"&B20 -> SAxx76 | J20: 000000608010167519 | K20: =IF(LEN(J20)<>18,"طول خاطئ",TEXT(98-MOD(VALUE(MOD(VALUE(MOD(VALUE(MOD(VALUE(MID(N20,1,9)),97)&MID(N20,10,7)),97)&MID(N20,17,7)),97)&MID(N20,24,7)),97),"00")) -> 12 | L20: =IF(LEN(J20)<>18,"","SA"&K20&" "&MID(B20&J20,1,4)&" "&MID(B20&J20,5,4)&" "&MID(B20&J20,9,4)&" "&MID(B20&J20,13,4)&" "&MID(B20&J20,17,4)) -> SA12 7600 0000 6080 1016 7519 | M20: =IF(LEN(J20)<>18,"",IF(MOD(VALUE(MOD(VALUE(MOD(VALUE(MOD(VALUE(MID((B20&J20&"2810"&K20),1,9)),97)&MID((B20&J20&"2810"&K20),10,7)),97)&MID((B20&J20&"2810"&K20),17,7)),97)&MID((B20&J20&"2810"&K20),24,7)),97)=1,"صحيح ✓","خطأ")) -> صحيح ✓ | N20: =B20&J20&"281000" -> 76000000608010167519281000
A21: 17 | B21: 78 | C21: بنك إس تي سي (STC Bank) | D21: STC Bank | E21: STCJSARI | F21: مؤكد | G21: بنك رقمي | H21: مصدر واحد: آيبان منشور SA47 7800 0000 0011 8115 9355 يجتاز MOD-97 — يُستحسن التأكد من ساما | I21: ="SA"&"xx"&B21 -> SAxx78 | J21: 000000608010167519 | K21: =IF(LEN(J21)<>18,"طول خاطئ",TEXT(98-MOD(VALUE(MOD(VALUE(MOD(VALUE(MOD(VALUE(MID(N21,1,9)),97)&MID(N21,10,7)),97)&MID(N21,17,7)),97)&MID(N21,24,7)),97),"00")) -> 56 | L21: =IF(LEN(J21)<>18,"","SA"&K21&" "&MID(B21&J21,1,4)&" "&MID(B21&J21,5,4)&" "&MID(B21&J21,9,4)&" "&MID(B21&J21,13,4)&" "&MID(B21&J21,17,4)) -> SA56 7800 0000 6080 1016 7519 | M21: =IF(LEN(J21)<>18,"",IF(MOD(VALUE(MOD(VALUE(MOD(VALUE(MOD(VALUE(MID((B21&J21&"2810"&K21),1,9)),97)&MID((B21&J21&"2810"&K21),10,7)),97)&MID((B21&J21&"2810"&K21),17,7)),97)&MID((B21&J21&"2810"&K21),24,7)),97)=1,"صحيح ✓","خطأ")) -> صحيح ✓ | N21: =B21&J21&"281000" -> 78000000608010167519281000
A22: 18 | B22: 80 | C22: مصرف الراجحي | D22: Al Rajhi Bank | E22: RJHISARI | F22: مؤكد | G22: نشط | I22: ="SA"&"xx"&B22 -> SAxx80 | J22: 000000608010167519 | K22: =IF(LEN(J22)<>18,"طول خاطئ",TEXT(98-MOD(VALUE(MOD(VALUE(MOD(VALUE(MOD(VALUE(MID(N22,1,9)),97)&MID(N22,10,7)),97)&MID(N22,17,7)),97)&MID(N22,24,7)),97),"00")) -> 03 | L22: =IF(LEN(J22)<>18,"","SA"&K22&" "&MID(B22&J22,1,4)&" "&MID(B22&J22,5,4)&" "&MID(B22&J22,9,4)&" "&MID(B22&J22,13,4)&" "&MID(B22&J22,17,4)) -> SA03 8000 0000 6080 1016 7519 | M22: =IF(LEN(J22)<>18,"",IF(MOD(VALUE(MOD(VALUE(MOD(VALUE(MOD(VALUE(MID((B22&J22&"2810"&K22),1,9)),97)&MID((B22&J22&"2810"&K22),10,7)),97)&MID((B22&J22&"2810"&K22),17,7)),97)&MID((B22&J22&"2810"&K22),24,7)),97)=1,"صحيح ✓","خطأ")) -> صحيح ✓ | N22: =B22&J22&"281000" -> 80000000608010167519281000
A23: 19 | B23: 81 | C23: دويتشه بنك (فرع السعودية) | D23: Deutsche Bank | E23: DEUTSARI | F23: مصدر واحد | G23: فرع بنك أجنبي | I23: ="SA"&"xx"&B23 -> SAxx81 | J23: 000000608010167519 | K23: =IF(LEN(J23)<>18,"طول خاطئ",TEXT(98-MOD(VALUE(MOD(VALUE(MOD(VALUE(MOD(VALUE(MID(N23,1,9)),97)&MID(N23,10,7)),97)&MID(N23,17,7)),97)&MID(N23,24,7)),97),"00")) -> 25 | L23: =IF(LEN(J23)<>18,"","SA"&K23&" "&MID(B23&J23,1,4)&" "&MID(B23&J23,5,4)&" "&MID(B23&J23,9,4)&" "&MID(B23&J23,13,4)&" "&MID(B23&J23,17,4)) -> SA25 8100 0000 6080 1016 7519 | M23: =IF(LEN(J23)<>18,"",IF(MOD(VALUE(MOD(VALUE(MOD(VALUE(MOD(VALUE(MID((B23&J23&"2810"&K23),1,9)),97)&MID((B23&J23&"2810"&K23),10,7)),97)&MID((B23&J23&"2810"&K23),17,7)),97)&MID((B23&J23&"2810"&K23),24,7)),97)=1,"صحيح ✓","خطأ")) -> صحيح ✓ | N23: =B23&J23&"281000" -> 81000000608010167519281000
A24: 20 | B24: 82 | C24: البنك الوطني الباكستاني (فرع السعودية) | D24: National Bank of Pakistan | E24: NBPASARI | F24: مؤكد (ورد NBOPSARI في جدول واحد) | G24: فرع بنك أجنبي | I24: ="SA"&"xx"&B24 -> SAxx82 | J24: 000000608010167519 | K24: =IF(LEN(J24)<>18,"طول خاطئ",TEXT(98-MOD(VALUE(MOD(VALUE(MOD(VALUE(MOD(VALUE(MID(N24,1,9)),97)&MID(N24,10,7)),97)&MID(N24,17,7)),97)&MID(N24,24,7)),97),"00")) -> 47 | L24: =IF(LEN(J24)<>18,"","SA"&K24&" "&MID(B24&J24,1,4)&" "&MID(B24&J24,5,4)&" "&MID(B24&J24,9,4)&" "&MID(B24&J24,13,4)&" "&MID(B24&J24,17,4)) -> SA47 8200 0000 6080 1016 7519 | M24: =IF(LEN(J24)<>18,"",IF(MOD(VALUE(MOD(VALUE(MOD(VALUE(MOD(VALUE(MID((B24&J24&"2810"&K24),1,9)),97)&MID((B24&J24&"2810"&K24),10,7)),97)&MID((B24&J24&"2810"&K24),17,7)),97)&MID((B24&J24&"2810"&K24),24,7)),97)=1,"صحيح ✓","خطأ")) -> صحيح ✓ | N24: =B24&J24&"281000" -> 82000000608010167519281000
A25: 21 | B25: 83 | C25: بنك الدولة الهندي (فرع السعودية) | D25: State Bank of India | E25: SBINSAJE | F25: مصدر واحد | G25: فرع بنك أجنبي | H25: مصدر واحد فقط — يُستحسن التأكد من ساما | I25: ="SA"&"xx"&B25 -> SAxx83 | J25: 000000608010167519 | K25: =IF(LEN(J25)<>18,"طول خاطئ",TEXT(98-MOD(VALUE(MOD(VALUE(MOD(VALUE(MOD(VALUE(MID(N25,1,9)),97)&MID(N25,10,7)),97)&MID(N25,17,7)),97)&MID(N25,24,7)),97),"00")) -> 69 | L25: =IF(LEN(J25)<>18,"","SA"&K25&" "&MID(B25&J25,1,4)&" "&MID(B25&J25,5,4)&" "&MID(B25&J25,9,4)&" "&MID(B25&J25,13,4)&" "&MID(B25&J25,17,4)) -> SA69 8300 0000 6080 1016 7519 | M25: =IF(LEN(J25)<>18,"",IF(MOD(VALUE(MOD(VALUE(MOD(VALUE(MOD(VALUE(MID((B25&J25&"2810"&K25),1,9)),97)&MID((B25&J25&"2810"&K25),10,7)),97)&MID((B25&J25&"2810"&K25),17,7)),97)&MID((B25&J25&"2810"&K25),24,7)),97)=1,"صحيح ✓","خطأ")) -> صحيح ✓ | N25: =B25&J25&"281000" -> 83000000608010167519281000
A26: 22 | B26: 84 | C26: بنك زراعات التركي (فرع السعودية) | D26: T.C. Ziraat Bankası | E26: TCZBSAJE | F26: مصدر واحد | G26: فرع بنك أجنبي | I26: ="SA"&"xx"&B26 -> SAxx84 | J26: 000000608010167519 | K26: =IF(LEN(J26)<>18,"طول خاطئ",TEXT(98-MOD(VALUE(MOD(VALUE(MOD(VALUE(MOD(VALUE(MID(N26,1,9)),97)&MID(N26,10,7)),97)&MID(N26,17,7)),97)&MID(N26,24,7)),97),"00")) -> 91 | L26: =IF(LEN(J26)<>18,"","SA"&K26&" "&MID(B26&J26,1,4)&" "&MID(B26&J26,5,4)&" "&MID(B26&J26,9,4)&" "&MID(B26&J26,13,4)&" "&MID(B26&J26,17,4)) -> SA91 8400 0000 6080 1016 7519 | M26: =IF(LEN(J26)<>18,"",IF(MOD(VALUE(MOD(VALUE(MOD(VALUE(MOD(VALUE(MID((B26&J26&"2810"&K26),1,9)),97)&MID((B26&J26&"2810"&K26),10,7)),97)&MID((B26&J26&"2810"&K26),17,7)),97)&MID((B26&J26&"2810"&K26),24,7)),97)=1,"صحيح ✓","خطأ")) -> صحيح ✓ | N26: =B26&J26&"281000" -> 84000000608010167519281000
A27: 23 | B27: 85 | C27: بي إن بي باريبا (فرع السعودية) | D27: BNP Paribas | E27: BNPASARI | F27: غير مؤكد (الملف الاسترشادي فقط) | G27: فرع بنك أجنبي | I27: ="SA"&"xx"&B27 -> SAxx85 | J27: 000000608010167519 | K27: =IF(LEN(J27)<>18,"طول خاطئ",TEXT(98-MOD(VALUE(MOD(VALUE(MOD(VALUE(MOD(VALUE(MID(N27,1,9)),97)&MID(N27,10,7)),97)&MID(N27,17,7)),97)&MID(N27,24,7)),97),"00")) -> 16 | L27: =IF(LEN(J27)<>18,"","SA"&K27&" "&MID(B27&J27,1,4)&" "&MID(B27&J27,5,4)&" "&MID(B27&J27,9,4)&" "&MID(B27&J27,13,4)&" "&MID(B27&J27,17,4)) -> SA16 8500 0000 6080 1016 7519 | M27: =IF(LEN(J27)<>18,"",IF(MOD(VALUE(MOD(VALUE(MOD(VALUE(MOD(VALUE(MID((B27&J27&"2810"&K27),1,9)),97)&MID((B27&J27&"2810"&K27),10,7)),97)&MID((B27&J27&"2810"&K27),17,7)),97)&MID((B27&J27&"2810"&K27),24,7)),97)=1,"صحيح ✓","خطأ")) -> صحيح ✓ | N27: =B27&J27&"281000" -> 85000000608010167519281000
A28: 24 | B28: 86 | C28: جي بي مورغان تشيس (فرع السعودية) | D28: JPMorgan Chase Bank | E28: CHASSARI | F28: غير مؤكد (ورد CHASSARISAU لشركة JPMorgan السعودية) | G28: فرع بنك أجنبي | I28: ="SA"&"xx"&B28 -> SAxx86 | J28: 000000608010167519 | K28: =IF(LEN(J28)<>18,"طول خاطئ",TEXT(98-MOD(VALUE(MOD(VALUE(MOD(VALUE(MOD(VALUE(MID(N28,1,9)),97)&MID(N28,10,7)),97)&MID(N28,17,7)),97)&MID(N28,24,7)),97),"00")) -> 38 | L28: =IF(LEN(J28)<>18,"","SA"&K28&" "&MID(B28&J28,1,4)&" "&MID(B28&J28,5,4)&" "&MID(B28&J28,9,4)&" "&MID(B28&J28,13,4)&" "&MID(B28&J28,17,4)) -> SA38 8600 0000 6080 1016 7519 | M28: =IF(LEN(J28)<>18,"",IF(MOD(VALUE(MOD(VALUE(MOD(VALUE(MOD(VALUE(MID((B28&J28&"2810"&K28),1,9)),97)&MID((B28&J28&"2810"&K28),10,7)),97)&MID((B28&J28&"2810"&K28),17,7)),97)&MID((B28&J28&"2810"&K28),24,7)),97)=1,"صحيح ✓","خطأ")) -> صحيح ✓ | N28: =B28&J28&"281000" -> 86000000608010167519281000
A29: 25 | B29: 90 | C29: بنك الخليج الدولي | D29: Gulf International Bank (GIB) | E29: GULFSARI | F29: غير مؤكد (الملف الاسترشادي فقط) | G29: فرع بنك أجنبي | I29: ="SA"&"xx"&B29 -> SAxx90 | J29: 000000608010167519 | K29: =IF(LEN(J29)<>18,"طول خاطئ",TEXT(98-MOD(VALUE(MOD(VALUE(MOD(VALUE(MOD(VALUE(MID(N29,1,9)),97)&MID(N29,10,7)),97)&MID(N29,17,7)),97)&MID(N29,24,7)),97),"00")) -> 29 | L29: =IF(LEN(J29)<>18,"","SA"&K29&" "&MID(B29&J29,1,4)&" "&MID(B29&J29,5,4)&" "&MID(B29&J29,9,4)&" "&MID(B29&J29,13,4)&" "&MID(B29&J29,17,4)) -> SA29 9000 0000 6080 1016 7519 | M29: =IF(LEN(J29)<>18,"",IF(MOD(VALUE(MOD(VALUE(MOD(VALUE(MOD(VALUE(MID((B29&J29&"2810"&K29),1,9)),97)&MID((B29&J29&"2810"&K29),10,7)),97)&MID((B29&J29&"2810"&K29),17,7)),97)&MID((B29&J29&"2810"&K29),24,7)),97)=1,"صحيح ✓","خطأ")) -> صحيح ✓ | N29: =B29&J29&"281000" -> 90000000608010167519281000
A30: 26 | B30: 95 | C30: بنك الإمارات دبي الوطني (فرع السعودية) | D30: Emirates NBD | E30: EBILSARI | F30: مصدر واحد + الملف الاسترشادي | G30: فرع بنك أجنبي | I30: ="SA"&"xx"&B30 -> SAxx95 | J30: 000000608010167519 | K30: =IF(LEN(J30)<>18,"طول خاطئ",TEXT(98-MOD(VALUE(MOD(VALUE(MOD(VALUE(MOD(VALUE(MID(N30,1,9)),97)&MID(N30,10,7)),97)&MID(N30,17,7)),97)&MID(N30,24,7)),97),"00")) -> 42 | L30: =IF(LEN(J30)<>18,"","SA"&K30&" "&MID(B30&J30,1,4)&" "&MID(B30&J30,5,4)&" "&MID(B30&J30,9,4)&" "&MID(B30&J30,13,4)&" "&MID(B30&J30,17,4)) -> SA42 9500 0000 6080 1016 7519 | M30: =IF(LEN(J30)<>18,"",IF(MOD(VALUE(MOD(VALUE(MOD(VALUE(MOD(VALUE(MID((B30&J30&"2810"&K30),1,9)),97)&MID((B30&J30&"2810"&K30),10,7)),97)&MID((B30&J30&"2810"&K30),17,7)),97)&MID((B30&J30&"2810"&K30),24,7)),97)=1,"صحيح ✓","خطأ")) -> صحيح ✓ | N30: =B30&J30&"281000" -> 95000000608010167519281000
A32: المصادر: معرّفات البنوك التي تصدرها ساما كما ينشرها github.com/EngMEita/saudi-banks، مع مراجعة cubbbix.com و validatefin.com (أكتوبر 2026). الرمزان 78 (STC Bank) و83 وردا في مصدر واحد. الرمزان 36 (D360) و73 (بنك أبوظبي الأول) مؤكدان بآيبانات فعلية قدّمها المستخدم. Vision Bank لم يُدرج لأن رمزه لم يُتحقق منه؛ يُعرف من الخانتين 5–6 في أي آيبان صادر منه ويُضاف في صف جديد. رموز SWIFT: ثماني خانات للمركز الرئيسي (تُضاف XXX لصيغة 11 خانة)، من أدلة SWIFT العامة (Wise، XE، theswiftcodes، ksaexpats، alaan) — «مؤكد» = أكثر من مصدر، «مصدر واحد» و«غير مؤكد» يُتحقق منهما مع البنك قبل التحويل.
A33: مفتاح الألوان: الخلايا الصفراء بخط أزرق مدخلات يمكن تعديلها؛ الباقي معادلات.

Sheet التحقق من الآيبان
A1: التحقق من صحة الآيبان السعودي — خوارزمية ISO 7064 MOD 97-10
A2: اكتب أو الصق الآيبان في العمود A (بمسافات أو بدونها). النتيجة والسبب وحقل التدقيق الصحيح تظهر آلياً. الأعمدة من L فما بعد محرك الحساب.
A4: الآيبان (مدخل) | B4: بعد التنظيف | C4: الطول | D4: الدولة | E4: حقل التدقيق المُدخل | F4: رمز البنك | G4: اسم البنك | H4: باقي القسمة على 97 | I4: حقل التدقيق الصحيح لهذا الحساب | J4: النتيجة | K4: السبب | L4: المُعاد ترتيبه | M4: صالح الرموز | N4: ح1 | O4: ح2 | P4: ح3 | Q4: ح4 | R4: ح5 | S4: ح6 | T4: ح7 | U4: ح8 | V4: ح9 | W4: ح10 | X4: ح11 | Y4: ح12 | Z4: ح13 | AA4: ح14 | AB4: ح15 | AC4: ح16 | AD4: ح17 | AE4: ح18 | AF4: ح19 | AG4: ح20 | AH4: ح21 | AI4: ح22 | AJ4: ح23 | AK4: ح24 | AL4: ح25 | AM4: ح26 | AN4: ح27 | AO4: ح28 | AP4: ح29 | AQ4: ح30 | AR4: ح31 | AS4: ح32 | AT4: ح33 | AU4: ح34 | AV4: السلسلة الرقمية | AW4: باقي 1 | AX4: باقي 2 | AY4: باقي 3 | AZ4: باقي 4 | BA4: باقي 5 | BB4: باقي 6 | BC4: باقي 7 | BD4: باقي 8 | BE4: باقي 9 | BF4: باقي 10
A5: SA03 8000 0000 6080 1016 7519 | B5: =UPPER(SUBSTITUTE(SUBSTITUTE(SUBSTITUTE(TRIM(A5)," ",""),"-",""),CHAR(160),"")) -> SA0380000000608010167519 | C5: =IF(B5="","",LEN(B5)) -> 24 | D5: =IF(B5="","",LEFT(B5,2)) -> SA | E5: =IF(B5="","",MID(B5,3,2)) -> 03 | F5: =IF(B5="","",MID(B5,5,2)) -> 80 | G5: =IF(B5="","",IFERROR(INDEX('رموز البنوك'!$C$5:$C$30,MATCH(F5,'رموز البنوك'!$B$5:$B$30,0)),"رمز غير معروف")) -> مصرف الراجحي | H5: =BF5 -> 1 | I5: =IF(OR(H5="",NOT(AND(ISNUMBER(FIND(MID(B5,3,1),"0123456789")),ISNUMBER(FIND(MID(B5,4,1),"0123456789"))))),"",TEXT(98-MOD(H5-VALUE(E5),97),"00")) -> 03 | J5: =IF(B5="","",IF(LEFT(K5,10)="آيبان صحيح","صحيح ✓","غير صحيح ✗")) -> صحيح ✓ | K5: =IF(B5="","",IF(M5=FALSE(),"يحتوي رموزاً غير مسموحة (المسموح A–Z و 0–9 فقط)",IF(D5<>"SA","رمز الدولة "&D5&" — هذا المدقق للآيبان السعودي SA",IF(C5<>24,"الطول "&C5&" خانة والمطلوب 24",IF(NOT(AND(ISNUMBER(FIND(MID(B5,3,1),"0123456789")),ISNUMBER(FIND(MID(B5,4,1),"0123456789")))),"خانتا التدقيق يجب أن تكونا رقمين",IF(ISERROR(VALUE(MID(B5,5,20))),"رمز البنك ورقم الحساب يجب أن يكونا أرقاماً",IF(H5<>1,"فشل اختبار MOD-97 (الباقي "&H5&" وليس 1) — خطأ في كتابة الرقم؛ خانتا التدقيق الصحيحتان لهذا الحساب "&I5,IF(G5="رمز غير معروف","اجتاز MOD-97 لكن رمز البنك "&F5&" غير مسجل في جدول البنوك","آيبان صحيح — "&G5)))))))) -> آيبان صحيح — مصرف الراجحي | L5: =IF(B5="","",MID(B5,5,40)&LEFT(B5,4)) -> 80000000608010167519SA03 | M5: =IF(L5="","",NOT(ISNUMBER(FIND("#",AV5)))) -> TRUE | N5: =IF(LEN($L5)<1,"",IF(ISNUMBER(FIND(MID($L5,1,1),"0123456789")),MID($L5,1,1),IF(ISNUMBER(FIND(MID($L5,1,1),"ABCDEFGHIJKLMNOPQRSTUVWXYZ")),CODE(MID($L5,1,1))-55,"#"))) -> 8 | O5: =IF(LEN($L5)<2,"",IF(ISNUMBER(FIND(MID($L5,2,1),"0123456789")),MID($L5,2,1),IF(ISNUMBER(FIND(MID($L5,2,1),"ABCDEFGHIJKLMNOPQRSTUVWXYZ")),CODE(MID($L5,2,1))-55,"#"))) -> 0 | P5: =IF(LEN($L5)<3,"",IF(ISNUMBER(FIND(MID($L5,3,1),"0123456789")),MID($L5,3,1),IF(ISNUMBER(FIND(MID($L5,3,1),"ABCDEFGHIJKLMNOPQRSTUVWXYZ")),CODE(MID($L5,3,1))-55,"#"))) -> 0 | Q5: =IF(LEN($L5)<4,"",IF(ISNUMBER(FIND(MID($L5,4,1),"0123456789")),MID($L5,4,1),IF(ISNUMBER(FIND(MID($L5,4,1),"ABCDEFGHIJKLMNOPQRSTUVWXYZ")),CODE(MID($L5,4,1))-55,"#"))) -> 0 | R5: =IF(LEN($L5)<5,"",IF(ISNUMBER(FIND(MID($L5,5,1),"0123456789")),MID($L5,5,1),IF(ISNUMBER(FIND(MID($L5,5,1),"ABCDEFGHIJKLMNOPQRSTUVWXYZ")),CODE(MID($L5,5,1))-55,"#"))) -> 0 | S5: =IF(LEN($L5)<6,"",IF(ISNUMBER(FIND(MID($L5,6,1),"0123456789")),MID($L5,6,1),IF(ISNUMBER(FIND(MID($L5,6,1),"ABCDEFGHIJKLMNOPQRSTUVWXYZ")),CODE(MID($L5,6,1))-55,"#"))) -> 0 | T5: =IF(LEN($L5)<7,"",IF(ISNUMBER(FIND(MID($L5,7,1),"0123456789")),MID($L5,7,1),IF(ISNUMBER(FIND(MID($L5,7,1),"ABCDEFGHIJKLMNOPQRSTUVWXYZ")),CODE(MID($L5,7,1))-55,"#"))) -> 0 | U5: =IF(LEN($L5)<8,"",IF(ISNUMBER(FIND(MID($L5,8,1),"0123456789")),MID($L5,8,1),IF(ISNUMBER(FIND(MID($L5,8,1),"ABCDEFGHIJKLMNOPQRSTUVWXYZ")),CODE(MID($L5,8,1))-55,"#"))) -> 0 | V5: =IF(LEN($L5)<9,"",IF(ISNUMBER(FIND(MID($L5,9,1),"0123456789")),MID($L5,9,1),IF(ISNUMBER(FIND(MID($L5,9,1),"ABCDEFGHIJKLMNOPQRSTUVWXYZ")),CODE(MID($L5,9,1))-55,"#"))) -> 6 | W5: =IF(LEN($L5)<10,"",IF(ISNUMBER(FIND(MID($L5,10,1),"0123456789")),MID($L5,10,1),IF(ISNUMBER(FIND(MID($L5,10,1),"ABCDEFGHIJKLMNOPQRSTUVWXYZ")),CODE(MID($L5,10,1))-55,"#"))) -> 0 | X5: =IF(LEN($L5)<11,"",IF(ISNUMBER(FIND(MID($L5,11,1),"0123456789")),MID($L5,11,1),IF(ISNUMBER(FIND(MID($L5,11,1),"ABCDEFGHIJKLMNOPQRSTUVWXYZ")),CODE(MID($L5,11,1))-55,"#"))) -> 8 | Y5: =IF(LEN($L5)<12,"",IF(ISNUMBER(FIND(MID($L5,12,1),"0123456789")),MID($L5,12,1),IF(ISNUMBER(FIND(MID($L5,12,1),"ABCDEFGHIJKLMNOPQRSTUVWXYZ")),CODE(MID($L5,12,1))-55,"#"))) -> 0 | Z5: =IF(LEN($L5)<13,"",IF(ISNUMBER(FIND(MID($L5,13,1),"0123456789")),MID($L5,13,1),IF(ISNUMBER(FIND(MID($L5,13,1),"ABCDEFGHIJKLMNOPQRSTUVWXYZ")),CODE(MID($L5,13,1))-55,"#"))) -> 1 | AA5: =IF(LEN($L5)<14,"",IF(ISNUMBER(FIND(MID($L5,14,1),"0123456789")),MID($L5,14,1),IF(ISNUMBER(FIND(MID($L5,14,1),"ABCDEFGHIJKLMNOPQRSTUVWXYZ")),CODE(MID($L5,14,1))-55,"#"))) -> 0 | AB5: =IF(LEN($L5)<15,"",IF(ISNUMBER(FIND(MID($L5,15,1),"0123456789")),MID($L5,15,1),IF(ISNUMBER(FIND(MID($L5,15,1),"ABCDEFGHIJKLMNOPQRSTUVWXYZ")),CODE(MID($L5,15,1))-55,"#"))) -> 1 | AC5: =IF(LEN($L5)<16,"",IF(ISNUMBER(FIND(MID($L5,16,1),"0123456789")),MID($L5,16,1),IF(ISNUMBER(FIND(MID($L5,16,1),"ABCDEFGHIJKLMNOPQRSTUVWXYZ")),CODE(MID($L5,16,1))-55,"#"))) -> 6 | AD5: =IF(LEN($L5)<17,"",IF(ISNUMBER(FIND(MID($L5,17,1),"0123456789")),MID($L5,17,1),IF(ISNUMBER(FIND(MID($L5,17,1),"ABCDEFGHIJKLMNOPQRSTUVWXYZ")),CODE(MID($L5,17,1))-55,"#"))) -> 7 | AE5: =IF(LEN($L5)<18,"",IF(ISNUMBER(FIND(MID($L5,18,1),"0123456789")),MID($L5,18,1),IF(ISNUMBER(FIND(MID($L5,18,1),"ABCDEFGHIJKLMNOPQRSTUVWXYZ")),CODE(MID($L5,18,1))-55,"#"))) -> 5 | AF5: =IF(LEN($L5)<19,"",IF(ISNUMBER(FIND(MID($L5,19,1),"0123456789")),MID($L5,19,1),IF(ISNUMBER(FIND(MID($L5,19,1),"ABCDEFGHIJKLMNOPQRSTUVWXYZ")),CODE(MID($L5,19,1))-55,"#"))) -> 1 | AG5: =IF(LEN($L5)<20,"",IF(ISNUMBER(FIND(MID($L5,20,1),"0123456789")),MID($L5,20,1),IF(ISNUMBER(FIND(MID($L5,20,1),"ABCDEFGHIJKLMNOPQRSTUVWXYZ")),CODE(MID($L5,20,1))-55,"#"))) -> 9 | AH5: =IF(LEN($L5)<21,"",IF(ISNUMBER(FIND(MID($L5,21,1),"0123456789")),MID($L5,21,1),IF(ISNUMBER(FIND(MID($L5,21,1),"ABCDEFGHIJKLMNOPQRSTUVWXYZ")),CODE(MID($L5,21,1))-55,"#"))) -> 28 | AI5: =IF(LEN($L5)<22,"",IF(ISNUMBER(FIND(MID($L5,22,1),"0123456789")),MID($L5,22,1),IF(ISNUMBER(FIND(MID($L5,22,1),"ABCDEFGHIJKLMNOPQRSTUVWXYZ")),CODE(MID($L5,22,1))-55,"#"))) -> 10 | AJ5: =IF(LEN($L5)<23,"",IF(ISNUMBER(FIND(MID($L5,23,1),"0123456789")),MID($L5,23,1),IF(ISNUMBER(FIND(MID($L5,23,1),"ABCDEFGHIJKLMNOPQRSTUVWXYZ")),CODE(MID($L5,23,1))-55,"#"))) -> 0 | AK5: =IF(LEN($L5)<24,"",IF(ISNUMBER(FIND(MID($L5,24,1),"0123456789")),MID($L5,24,1),IF(ISNUMBER(FIND(MID($L5,24,1),"ABCDEFGHIJKLMNOPQRSTUVWXYZ")),CODE(MID($L5,24,1))-55,"#"))) -> 3 | AL5: =IF(LEN($L5)<25,"",IF(ISNUMBER(FIND(MID($L5,25,1),"0123456789")),MID($L5,25,1),IF(ISNUMBER(FIND(MID($L5,25,1),"ABCDEFGHIJKLMNOPQRSTUVWXYZ")),CODE(MID($L5,25,1))-55,"#"))) | AM5: =IF(LEN($L5)<26,"",IF(ISNUMBER(FIND(MID($L5,26,1),"0123456789")),MID($L5,26,1),IF(ISNUMBER(FIND(MID($L5,26,1),"ABCDEFGHIJKLMNOPQRSTUVWXYZ")),CODE(MID($L5,26,1))-55,"#"))) | AN5: =IF(LEN($L5)<27,"",IF(ISNUMBER(FIND(MID($L5,27,1),"0123456789")),MID($L5,27,1),IF(ISNUMBER(FIND(MID($L5,27,1),"ABCDEFGHIJKLMNOPQRSTUVWXYZ")),CODE(MID($L5,27,1))-55,"#"))) | AO5: =IF(LEN($L5)<28,"",IF(ISNUMBER(FIND(MID($L5,28,1),"0123456789")),MID($L5,28,1),IF(ISNUMBER(FIND(MID($L5,28,1),"ABCDEFGHIJKLMNOPQRSTUVWXYZ")),CODE(MID($L5,28,1))-55,"#"))) | AP5: =IF(LEN($L5)<29,"",IF(ISNUMBER(FIND(MID($L5,29,1),"0123456789")),MID($L5,29,1),IF(ISNUMBER(FIND(MID($L5,29,1),"ABCDEFGHIJKLMNOPQRSTUVWXYZ")),CODE(MID($L5,29,1))-55,"#"))) | AQ5: =IF(LEN($L5)<30,"",IF(ISNUMBER(FIND(MID($L5,30,1),"0123456789")),MID($L5,30,1),IF(ISNUMBER(FIND(MID($L5,30,1),"ABCDEFGHIJKLMNOPQRSTUVWXYZ")),CODE(MID($L5,30,1))-55,"#"))) | AR5: =IF(LEN($L5)<31,"",IF(ISNUMBER(FIND(MID($L5,31,1),"0123456789")),MID($L5,31,1),IF(ISNUMBER(FIND(MID($L5,31,1),"ABCDEFGHIJKLMNOPQRSTUVWXYZ")),CODE(MID($L5,31,1))-55,"#"))) | AS5: =IF(LEN($L5)<32,"",IF(ISNUMBER(FIND(MID($L5,32,1),"0123456789")),MID($L5,32,1),IF(ISNUMBER(FIND(MID($L5,32,1),"ABCDEFGHIJKLMNOPQRSTUVWXYZ")),CODE(MID($L5,32,1))-55,"#"))) | AT5: =IF(LEN($L5)<33,"",IF(ISNUMBER(FIND(MID($L5,33,1),"0123456789")),MID($L5,33,1),IF(ISNUMBER(FIND(MID($L5,33,1),"ABCDEFGHIJKLMNOPQRSTUVWXYZ")),CODE(MID($L5,33,1))-55,"#"))) | AU5: =IF(LEN($L5)<34,"",IF(ISNUMBER(FIND(MID($L5,34,1),"0123456789")),MID($L5,34,1),IF(ISNUMBER(FIND(MID($L5,34,1),"ABCDEFGHIJKLMNOPQRSTUVWXYZ")),CODE(MID($L5,34,1))-55,"#"))) | AV5: =_xlfn.CONCAT(N5:AU5) -> 80000000608010167519281003 | AW5: =IF(OR(AV5="",M5=FALSE()),"",MOD(VALUE(MID(AV5,1,9)),97)) -> 72 | AX5: =IF(AW5="","",MOD(VALUE(AW5&MID(AV5,10,7)),97)) -> 30 | AY5: =IF(AX5="","",MOD(VALUE(AX5&MID(AV5,17,7)),97)) -> 84 | AZ5: =IF(AY5="","",MOD(VALUE(AY5&MID(AV5,24,7)),97)) -> 1 | BA5: =IF(AZ5="","",MOD(VALUE(AZ5&MID(AV5,31,7)),97)) -> 1 | BB5: =IF(BA5="","",MOD(VALUE(BA5&MID(AV5,38,7)),97)) -> 1 | BC5: =IF(BB5="","",MOD(VALUE(BB5&MID(AV5,45,7)),97)) -> 1 | BD5: =IF(BC5="","",MOD(VALUE(BC5&MID(AV5,52,7)),97)) -> 1 | BE5: =IF(BD5="","",MOD(VALUE(BD5&MID(AV5,59,7)),97)) -> 1 | BF5: =IF(BE5="","",MOD(VALUE(BE5&MID(AV5,66,7)),97)) -> 1
A6: SA04 8000 0000 6080 1016 7519 | B6: =UPPER(SUBSTITUTE(SUBSTITUTE(SUBSTITUTE(TRIM(A6)," ",""),"-",""),CHAR(160),"")) -> SA0480000000608010167519 | C6: =IF(B6="","",LEN(B6)) -> 24 | D6: =IF(B6="","",LEFT(B6,2)) -> SA | E6: =IF(B6="","",MID(B6,3,2)) -> 04 | F6: =IF(B6="","",MID(B6,5,2)) -> 80 | G6: =IF(B6="","",IFERROR(INDEX('رموز البنوك'!$C$5:$C$30,MATCH(F6,'رموز البنوك'!$B$5:$B$30,0)),"رمز غير معروف")) -> مصرف الراجحي | H6: =BF6 -> 2 | I6: =IF(OR(H6="",NOT(AND(ISNUMBER(FIND(MID(B6,3,1),"0123456789")),ISNUMBER(FIND(MID(B6,4,1),"0123456789"))))),"",TEXT(98-MOD(H6-VALUE(E6),97),"00")) -> 03 | J6: =IF(B6="","",IF(LEFT(K6,10)="آيبان صحيح","صحيح ✓","غير صحيح ✗")) -> غير صحيح ✗ | K6: =IF(B6="","",IF(M6=FALSE(),"يحتوي رموزاً غير مسموحة (المسموح A–Z و 0–9 فقط)",IF(D6<>"SA","رمز الدولة "&D6&" — هذا المدقق للآيبان السعودي SA",IF(C6<>24,"الطول "&C6&" خانة والمطلوب 24",IF(NOT(AND(ISNUMBER(FIND(MID(B6,3,1),"0123456789")),ISNUMBER(FIND(MID(B6,4,1),"0123456789")))),"خانتا التدقيق يجب أن تكونا رقمين",IF(ISERROR(VALUE(MID(B6,5,20))),"رمز البنك ورقم الحساب يجب أن يكونا أرقاماً",IF(H6<>1,"فشل اختبار MOD-97 (الباقي "&H6&" وليس 1) — خطأ في كتابة الرقم؛ خانتا التدقيق الصحيحتان لهذا الحساب "&I6,IF(G6="رمز غير معروف","اجتاز MOD-97 لكن رمز البنك "&F6&" غير مسجل في جدول البنوك","آيبان صحيح — "&G6)))))))) -> فشل اختبار MOD-97 (الباقي 2 وليس 1) — خطأ في كتابة الرقم؛ خانتا التدقيق الصحيحتان لهذا الحساب 03 | L6: =IF(B6="","",MID(B6,5,40)&LEFT(B6,4)) -> 80000000608010167519SA04 | M6: =IF(L6="","",NOT(ISNUMBER(FIND("#",AV6)))) -> TRUE | N6: =IF(LEN($L6)<1,"",IF(ISNUMBER(FIND(MID($L6,1,1),"0123456789")),MID($L6,1,1),IF(ISNUMBER(FIND(MID($L6,1,1),"ABCDEFGHIJKLMNOPQRSTUVWXYZ")),CODE(MID($L6,1,1))-55,"#"))) -> 8 | O6: =IF(LEN($L6)<2,"",IF(ISNUMBER(FIND(MID($L6,2,1),"0123456789")),MID($L6,2,1),IF(ISNUMBER(FIND(MID($L6,2,1),"ABCDEFGHIJKLMNOPQRSTUVWXYZ")),CODE(MID($L6,2,1))-55,"#"))) -> 0 | P6: =IF(LEN($L6)<3,"",IF(ISNUMBER(FIND(MID($L6,3,1),"0123456789")),MID($L6,3,1),IF(ISNUMBER(FIND(MID($L6,3,1),"ABCDEFGHIJKLMNOPQRSTUVWXYZ")),CODE(MID($L6,3,1))-55,"#"))) -> 0 | Q6: =IF(LEN($L6)<4,"",IF(ISNUMBER(FIND(MID($L6,4,1),"0123456789")),MID($L6,4,1),IF(ISNUMBER(FIND(MID($L6,4,1),"ABCDEFGHIJKLMNOPQRSTUVWXYZ")),CODE(MID($L6,4,1))-55,"#"))) -> 0 | R6: =IF(LEN($L6)<5,"",IF(ISNUMBER(FIND(MID($L6,5,1),"0123456789")),MID($L6,5,1),IF(ISNUMBER(FIND(MID($L6,5,1),"ABCDEFGHIJKLMNOPQRSTUVWXYZ")),CODE(MID($L6,5,1))-55,"#"))) -> 0 | S6: =IF(LEN($L6)<6,"",IF(ISNUMBER(FIND(MID($L6,6,1),"0123456789")),MID($L6,6,1),IF(ISNUMBER(FIND(MID($L6,6,1),"ABCDEFGHIJKLMNOPQRSTUVWXYZ")),CODE(MID($L6,6,1))-55,"#"))) -> 0 | T6: =IF(LEN($L6)<7,"",IF(ISNUMBER(FIND(MID($L6,7,1),"0123456789")),MID($L6,7,1),IF(ISNUMBER(FIND(MID($L6,7,1),"ABCDEFGHIJKLMNOPQRSTUVWXYZ")),CODE(MID($L6,7,1))-55,"#"))) -> 0 | U6: =IF(LEN($L6)<8,"",IF(ISNUMBER(FIND(MID($L6,8,1),"0123456789")),MID($L6,8,1),IF(ISNUMBER(FIND(MID($L6,8,1),"ABCDEFGHIJKLMNOPQRSTUVWXYZ")),CODE(MID($L6,8,1))-55,"#"))) -> 0 | V6: =IF(LEN($L6)<9,"",IF(ISNUMBER(FIND(MID($L6,9,1),"0123456789")),MID($L6,9,1),IF(ISNUMBER(FIND(MID($L6,9,1),"ABCDEFGHIJKLMNOPQRSTUVWXYZ")),CODE(MID($L6,9,1))-55,"#"))) -> 6 | W6: =IF(LEN($L6)<10,"",IF(ISNUMBER(FIND(MID($L6,10,1),"0123456789")),MID($L6,10,1),IF(ISNUMBER(FIND(MID($L6,10,1),"ABCDEFGHIJKLMNOPQRSTUVWXYZ")),CODE(MID($L6,10,1))-55,"#"))) -> 0 | X6: =IF(LEN($L6)<11,"",IF(ISNUMBER(FIND(MID($L6,11,1),"0123456789")),MID($L6,11,1),IF(ISNUMBER(FIND(MID($L6,11,1),"ABCDEFGHIJKLMNOPQRSTUVWXYZ")),CODE(MID($L6,11,1))-55,"#"))) -> 8 | Y6: =IF(LEN($L6)<12,"",IF(ISNUMBER(FIND(MID($L6,12,1),"0123456789")),MID($L6,12,1),IF(ISNUMBER(FIND(MID($L6,12,1),"ABCDEFGHIJKLMNOPQRSTUVWXYZ")),CODE(MID($L6,12,1))-55,"#"))) -> 0 | Z6: =IF(LEN($L6)<13,"",IF(ISNUMBER(FIND(MID($L6,13,1),"0123456789")),MID($L6,13,1),IF(ISNUMBER(FIND(MID($L6,13,1),"ABCDEFGHIJKLMNOPQRSTUVWXYZ")),CODE(MID($L6,13,1))-55,"#"))) -> 1 | AA6: =IF(LEN($L6)<14,"",IF(ISNUMBER(FIND(MID($L6,14,1),"0123456789")),MID($L6,14,1),IF(ISNUMBER(FIND(MID($L6,14,1),"ABCDEFGHIJKLMNOPQRSTUVWXYZ")),CODE(MID($L6,14,1))-55,"#"))) -> 0 | AB6: =IF(LEN($L6)<15,"",IF(ISNUMBER(FIND(MID($L6,15,1),"0123456789")),MID($L6,15,1),IF(ISNUMBER(FIND(MID($L6,15,1),"ABCDEFGHIJKLMNOPQRSTUVWXYZ")),CODE(MID($L6,15,1))-55,"#"))) -> 1 | AC6: =IF(LEN($L6)<16,"",IF(ISNUMBER(FIND(MID($L6,16,1),"0123456789")),MID($L6,16,1),IF(ISNUMBER(FIND(MID($L6,16,1),"ABCDEFGHIJKLMNOPQRSTUVWXYZ")),CODE(MID($L6,16,1))-55,"#"))) -> 6 | AD6: =IF(LEN($L6)<17,"",IF(ISNUMBER(FIND(MID($L6,17,1),"0123456789")),MID($L6,17,1),IF(ISNUMBER(FIND(MID($L6,17,1),"ABCDEFGHIJKLMNOPQRSTUVWXYZ")),CODE(MID($L6,17,1))-55,"#"))) -> 7 | AE6: =IF(LEN($L6)<18,"",IF(ISNUMBER(FIND(MID($L6,18,1),"0123456789")),MID($L6,18,1),IF(ISNUMBER(FIND(MID($L6,18,1),"ABCDEFGHIJKLMNOPQRSTUVWXYZ")),CODE(MID($L6,18,1))-55,"#"))) -> 5 | AF6: =IF(LEN($L6)<19,"",IF(ISNUMBER(FIND(MID($L6,19,1),"0123456789")),MID($L6,19,1),IF(ISNUMBER(FIND(MID($L6,19,1),"ABCDEFGHIJKLMNOPQRSTUVWXYZ")),CODE(MID($L6,19,1))-55,"#"))) -> 1 | AG6: =IF(LEN($L6)<20,"",IF(ISNUMBER(FIND(MID($L6,20,1),"0123456789")),MID($L6,20,1),IF(ISNUMBER(FIND(MID($L6,20,1),"ABCDEFGHIJKLMNOPQRSTUVWXYZ")),CODE(MID($L6,20,1))-55,"#"))) -> 9 | AH6: =IF(LEN($L6)<21,"",IF(ISNUMBER(FIND(MID($L6,21,1),"0123456789")),MID($L6,21,1),IF(ISNUMBER(FIND(MID($L6,21,1),"ABCDEFGHIJKLMNOPQRSTUVWXYZ")),CODE(MID($L6,21,1))-55,"#"))) -> 28 | AI6: =IF(LEN($L6)<22,"",IF(ISNUMBER(FIND(MID($L6,22,1),"0123456789")),MID($L6,22,1),IF(ISNUMBER(FIND(MID($L6,22,1),"ABCDEFGHIJKLMNOPQRSTUVWXYZ")),CODE(MID($L6,22,1))-55,"#"))) -> 10 | AJ6: =IF(LEN($L6)<23,"",IF(ISNUMBER(FIND(MID($L6,23,1),"0123456789")),MID($L6,23,1),IF(ISNUMBER(FIND(MID($L6,23,1),"ABCDEFGHIJKLMNOPQRSTUVWXYZ")),CODE(MID($L6,23,1))-55,"#"))) -> 0 | AK6: =IF(LEN($L6)<24,"",IF(ISNUMBER(FIND(MID($L6,24,1),"0123456789")),MID($L6,24,1),IF(ISNUMBER(FIND(MID($L6,24,1),"ABCDEFGHIJKLMNOPQRSTUVWXYZ")),CODE(MID($L6,24,1))-55,"#"))) -> 4 | AL6: =IF(LEN($L6)<25,"",IF(ISNUMBER(FIND(MID($L6,25,1),"0123456789")),MID($L6,25,1),IF(ISNUMBER(FIND(MID($L6,25,1),"ABCDEFGHIJKLMNOPQRSTUVWXYZ")),CODE(MID($L6,25,1))-55,"#"))) | AM6: =IF(LEN($L6)<26,"",IF(ISNUMBER(FIND(MID($L6,26,1),"0123456789")),MID($L6,26,1),IF(ISNUMBER(FIND(MID($L6,26,1),"ABCDEFGHIJKLMNOPQRSTUVWXYZ")),CODE(MID($L6,26,1))-55,"#"))) | AN6: =IF(LEN($L6)<27,"",IF(ISNUMBER(FIND(MID($L6,27,1),"0123456789")),MID($L6,27,1),IF(ISNUMBER(FIND(MID($L6,27,1),"ABCDEFGHIJKLMNOPQRSTUVWXYZ")),CODE(MID($L6,27,1))-55,"#"))) | AO6: =IF(LEN($L6)<28,"",IF(ISNUMBER(FIND(MID($L6,28,1),"0123456789")),MID($L6,28,1),IF(ISNUMBER(FIND(MID($L6,28,1),"ABCDEFGHIJKLMNOPQRSTUVWXYZ")),CODE(MID($L6,28,1))-55,"#"))) | AP6: =IF(LEN($L6)<29,"",IF(ISNUMBER(FIND(MID($L6,29,1),"0123456789")),MID($L6,29,1),IF(ISNUMBER(FIND(MID($L6,29,1),"ABCDEFGHIJKLMNOPQRSTUVWXYZ")),CODE(MID($L6,29,1))-55,"#"))) | AQ6: =IF(LEN($L6)<30,"",IF(ISNUMBER(FIND(MID($L6,30,1),"0123456789")),MID($L6,30,1),IF(ISNUMBER(FIND(MID($L6,30,1),"ABCDEFGHIJKLMNOPQRSTUVWXYZ")),CODE(MID($L6,30,1))-55,"#"))) | AR6: =IF(LEN($L6)<31,"",IF(ISNUMBER(FIND(MID($L6,31,1),"0123456789")),MID($L6,31,1),IF(ISNUMBER(FIND(MID($L6,31,1),"ABCDEFGHIJKLMNOPQRSTUVWXYZ")),CODE(MID($L6,31,1))-55,"#"))) | AS6: =IF(LEN($L6)<32,"",IF(ISNUMBER(FIND(MID($L6,32,1),"0123456789")),MID($L6,32,1),IF(ISNUMBER(FIND(MID($L6,32,1),"ABCDEFGHIJKLMNOPQRSTUVWXYZ")),CODE(MID($L6,32,1))-55,"#"))) | AT6: =IF(LEN($L6)<33,"",IF(ISNUMBER(FIND(MID($L6,33,1),"0123456789")),MID($L6,33,1),IF(ISNUMBER(FIND(MID($L6,33,1),"ABCDEFGHIJKLMNOPQRSTUVWXYZ")),CODE(MID($L6,33,1))-55,"#"))) | AU6: =IF(LEN($L6)<34,"",IF(ISNUMBER(FIND(MID($L6,34,1),"0123456789")),MID($L6,34,1),IF(ISNUMBER(FIND(MID($L6,34,1),"ABCDEFGHIJKLMNOPQRSTUVWXYZ")),CODE(MID($L6,34,1))-55,"#"))) | AV6: =_xlfn.CONCAT(N6:AU6) -> 80000000608010167519281004 | AW6: =IF(OR(AV6="",M6=FALSE()),"",MOD(VALUE(MID(AV6,1,9)),97)) -> 72 | AX6: =IF(AW6="","",MOD(VALUE(AW6&MID(AV6,10,7)),97)) -> 30 | AY6: =IF(AX6="","",MOD(VALUE(AX6&MID(AV6,17,7)),97)) -> 84 | AZ6: =IF(AY6="","",MOD(VALUE(AY6&MID(AV6,24,7)),97)) -> 2 | BA6: =IF(AZ6="","",MOD(VALUE(AZ6&MID(AV6,31,7)),97)) -> 2 | BB6: =IF(BA6="","",MOD(VALUE(BA6&MID(AV6,38,7)),97)) -> 2 | BC6: =IF(BB6="","",MOD(VALUE(BB6&MID(AV6,45,7)),97)) -> 2 | BD6: =IF(BC6="","",MOD(VALUE(BC6&MID(AV6,52,7)),97)) -> 2 | BE6: =IF(BD6="","",MOD(VALUE(BD6&MID(AV6,59,7)),97)) -> 2 | BF6: =IF(BE6="","",MOD(VALUE(BE6&MID(AV6,66,7)),97)) -> 2
A7: SA03 8000 0000 6080 1016 7591 | B7: =UPPER(SUBSTITUTE(SUBSTITUTE(SUBSTITUTE(TRIM(A7)," ",""),"-",""),CHAR(160),"")) -> SA0380000000608010167591 | C7: =IF(B7="","",LEN(B7)) -> 24 | D7: =IF(B7="","",LEFT(B7,2)) -> SA | E7: =IF(B7="","",MID(B7,3,2)) -> 03 | F7: =IF(B7="","",MID(B7,5,2)) -> 80 | G7: =IF(B7="","",IFERROR(INDEX('رموز البنوك'!$C$5:$C$30,MATCH(F7,'رموز البنوك'!$B$5:$B$30,0)),"رمز غير معروف")) -> مصرف الراجحي | H7: =BF7 -> 5 | I7: =IF(OR(H7="",NOT(AND(ISNUMBER(FIND(MID(B7,3,1),"0123456789")),ISNUMBER(FIND(MID(B7,4,1),"0123456789"))))),"",TEXT(98-MOD(H7-VALUE(E7),97),"00")) -> 96 | J7: =IF(B7="","",IF(LEFT(K7,10)="آيبان صحيح","صحيح ✓","غير صحيح ✗")) -> غير صحيح ✗ | K7: =IF(B7="","",IF(M7=FALSE(),"يحتوي رموزاً غير مسموحة (المسموح A–Z و 0–9 فقط)",IF(D7<>"SA","رمز الدولة "&D7&" — هذا المدقق للآيبان السعودي SA",IF(C7<>24,"الطول "&C7&" خانة والمطلوب 24",IF(NOT(AND(ISNUMBER(FIND(MID(B7,3,1),"0123456789")),ISNUMBER(FIND(MID(B7,4,1),"0123456789")))),"خانتا التدقيق يجب أن تكونا رقمين",IF(ISERROR(VALUE(MID(B7,5,20))),"رمز البنك ورقم الحساب يجب أن يكونا أرقاماً",IF(H7<>1,"فشل اختبار MOD-97 (الباقي "&H7&" وليس 1) — خطأ في كتابة الرقم؛ خانتا التدقيق الصحيحتان لهذا الحساب "&I7,IF(G7="رمز غير معروف","اجتاز MOD-97 لكن رمز البنك "&F7&" غير مسجل في جدول البنوك","آيبان صحيح — "&G7)))))))) -> فشل اختبار MOD-97 (الباقي 5 وليس 1) — خطأ في كتابة الرقم؛ خانتا التدقيق الصحيحتان لهذا الحساب 96 | L7: =IF(B7="","",MID(B7,5,40)&LEFT(B7,4)) -> 80000000608010167591SA03 | M7: =IF(L7="","",NOT(ISNUMBER(FIND("#",AV7)))) -> TRUE | N7: =IF(LEN($L7)<1,"",IF(ISNUMBER(FIND(MID($L7,1,1),"0123456789")),MID($L7,1,1),IF(ISNUMBER(FIND(MID($L7,1,1),"ABCDEFGHIJKLMNOPQRSTUVWXYZ")),CODE(MID($L7,1,1))-55,"#"))) -> 8 | O7: =IF(LEN($L7)<2,"",IF(ISNUMBER(FIND(MID($L7,2,1),"0123456789")),MID($L7,2,1),IF(ISNUMBER(FIND(MID($L7,2,1),"ABCDEFGHIJKLMNOPQRSTUVWXYZ")),CODE(MID($L7,2,1))-55,"#"))) -> 0 | P7: =IF(LEN($L7)<3,"",IF(ISNUMBER(FIND(MID($L7,3,1),"0123456789")),MID($L7,3,1),IF(ISNUMBER(FIND(MID($L7,3,1),"ABCDEFGHIJKLMNOPQRSTUVWXYZ")),CODE(MID($L7,3,1))-55,"#"))) -> 0 | Q7: =IF(LEN($L7)<4,"",IF(ISNUMBER(FIND(MID($L7,4,1),"0123456789")),MID($L7,4,1),IF(ISNUMBER(FIND(MID($L7,4,1),"ABCDEFGHIJKLMNOPQRSTUVWXYZ")),CODE(MID($L7,4,1))-55,"#"))) -> 0 | R7: =IF(LEN($L7)<5,"",IF(ISNUMBER(FIND(MID($L7,5,1),"0123456789")),MID($L7,5,1),IF(ISNUMBER(FIND(MID($L7,5,1),"ABCDEFGHIJKLMNOPQRSTUVWXYZ")),CODE(MID($L7,5,1))-55,"#"))) -> 0 | S7: =IF(LEN($L7)<6,"",IF(ISNUMBER(FIND(MID($L7,6,1),"0123456789")),MID($L7,6,1),IF(ISNUMBER(FIND(MID($L7,6,1),"ABCDEFGHIJKLMNOPQRSTUVWXYZ")),CODE(MID($L7,6,1))-55,"#"))) -> 0 | T7: =IF(LEN($L7)<7,"",IF(ISNUMBER(FIND(MID($L7,7,1),"0123456789")),MID($L7,7,1),IF(ISNUMBER(FIND(MID($L7,7,1),"ABCDEFGHIJKLMNOPQRSTUVWXYZ")),CODE(MID($L7,7,1))-55,"#"))) -> 0 | U7: =IF(LEN($L7)<8,"",IF(ISNUMBER(FIND(MID($L7,8,1),"0123456789")),MID($L7,8,1),IF(ISNUMBER(FIND(MID($L7,8,1),"ABCDEFGHIJKLMNOPQRSTUVWXYZ")),CODE(MID($L7,8,1))-55,"#"))) -> 0 | V7: =IF(LEN($L7)<9,"",IF(ISNUMBER(FIND(MID($L7,9,1),"0123456789")),MID($L7,9,1),IF(ISNUMBER(FIND(MID($L7,9,1),"ABCDEFGHIJKLMNOPQRSTUVWXYZ")),CODE(MID($L7,9,1))-55,"#"))) -> 6 | W7: =IF(LEN($L7)<10,"",IF(ISNUMBER(FIND(MID($L7,10,1),"0123456789")),MID($L7,10,1),IF(ISNUMBER(FIND(MID($L7,10,1),"ABCDEFGHIJKLMNOPQRSTUVWXYZ")),CODE(MID($L7,10,1))-55,"#"))) -> 0 | X7: =IF(LEN($L7)<11,"",IF(ISNUMBER(FIND(MID($L7,11,1),"0123456789")),MID($L7,11,1),IF(ISNUMBER(FIND(MID($L7,11,1),"ABCDEFGHIJKLMNOPQRSTUVWXYZ")),CODE(MID($L7,11,1))-55,"#"))) -> 8 | Y7: =IF(LEN($L7)<12,"",IF(ISNUMBER(FIND(MID($L7,12,1),"0123456789")),MID($L7,12,1),IF(ISNUMBER(FIND(MID($L7,12,1),"ABCDEFGHIJKLMNOPQRSTUVWXYZ")),CODE(MID($L7,12,1))-55,"#"))) -> 0 | Z7: =IF(LEN($L7)<13,"",IF(ISNUMBER(FIND(MID($L7,13,1),"0123456789")),MID($L7,13,1),IF(ISNUMBER(FIND(MID($L7,13,1),"ABCDEFGHIJKLMNOPQRSTUVWXYZ")),CODE(MID($L7,13,1))-55,"#"))) -> 1 | AA7: =IF(LEN($L7)<14,"",IF(ISNUMBER(FIND(MID($L7,14,1),"0123456789")),MID($L7,14,1),IF(ISNUMBER(FIND(MID($L7,14,1),"ABCDEFGHIJKLMNOPQRSTUVWXYZ")),CODE(MID($L7,14,1))-55,"#"))) -> 0 | AB7: =IF(LEN($L7)<15,"",IF(ISNUMBER(FIND(MID($L7,15,1),"0123456789")),MID($L7,15,1),IF(ISNUMBER(FIND(MID($L7,15,1),"ABCDEFGHIJKLMNOPQRSTUVWXYZ")),CODE(MID($L7,15,1))-55,"#"))) -> 1 | AC7: =IF(LEN($L7)<16,"",IF(ISNUMBER(FIND(MID($L7,16,1),"0123456789")),MID($L7,16,1),IF(ISNUMBER(FIND(MID($L7,16,1),"ABCDEFGHIJKLMNOPQRSTUVWXYZ")),CODE(MID($L7,16,1))-55,"#"))) -> 6 | AD7: =IF(LEN($L7)<17,"",IF(ISNUMBER(FIND(MID($L7,17,1),"0123456789")),MID($L7,17,1),IF(ISNUMBER(FIND(MID($L7,17,1),"ABCDEFGHIJKLMNOPQRSTUVWXYZ")),CODE(MID($L7,17,1))-55,"#"))) -> 7 | AE7: =IF(LEN($L7)<18,"",IF(ISNUMBER(FIND(MID($L7,18,1),"0123456789")),MID($L7,18,1),IF(ISNUMBER(FIND(MID($L7,18,1),"ABCDEFGHIJKLMNOPQRSTUVWXYZ")),CODE(MID($L7,18,1))-55,"#"))) -> 5 | AF7: =IF(LEN($L7)<19,"",IF(ISNUMBER(FIND(MID($L7,19,1),"0123456789")),MID($L7,19,1),IF(ISNUMBER(FIND(MID($L7,19,1),"ABCDEFGHIJKLMNOPQRSTUVWXYZ")),CODE(MID($L7,19,1))-55,"#"))) -> 9 | AG7: =IF(LEN($L7)<20,"",IF(ISNUMBER(FIND(MID($L7,20,1),"0123456789")),MID($L7,20,1),IF(ISNUMBER(FIND(MID($L7,20,1),"ABCDEFGHIJKLMNOPQRSTUVWXYZ")),CODE(MID($L7,20,1))-55,"#"))) -> 1 | AH7: =IF(LEN($L7)<21,"",IF(ISNUMBER(FIND(MID($L7,21,1),"0123456789")),MID($L7,21,1),IF(ISNUMBER(FIND(MID($L7,21,1),"ABCDEFGHIJKLMNOPQRSTUVWXYZ")),CODE(MID($L7,21,1))-55,"#"))) -> 28 | AI7: =IF(LEN($L7)<22,"",IF(ISNUMBER(FIND(MID($L7,22,1),"0123456789")),MID($L7,22,1),IF(ISNUMBER(FIND(MID($L7,22,1),"ABCDEFGHIJKLMNOPQRSTUVWXYZ")),CODE(MID($L7,22,1))-55,"#"))) -> 10 | AJ7: =IF(LEN($L7)<23,"",IF(ISNUMBER(FIND(MID($L7,23,1),"0123456789")),MID($L7,23,1),IF(ISNUMBER(FIND(MID($L7,23,1),"ABCDEFGHIJKLMNOPQRSTUVWXYZ")),CODE(MID($L7,23,1))-55,"#"))) -> 0 | AK7: =IF(LEN($L7)<24,"",IF(ISNUMBER(FIND(MID($L7,24,1),"0123456789")),MID($L7,24,1),IF(ISNUMBER(FIND(MID($L7,24,1),"ABCDEFGHIJKLMNOPQRSTUVWXYZ")),CODE(MID($L7,24,1))-55,"#"))) -> 3 | AL7: =IF(LEN($L7)<25,"",IF(ISNUMBER(FIND(MID($L7,25,1),"0123456789")),MID($L7,25,1),IF(ISNUMBER(FIND(MID($L7,25,1),"ABCDEFGHIJKLMNOPQRSTUVWXYZ")),CODE(MID($L7,25,1))-55,"#"))) | AM7: =IF(LEN($L7)<26,"",IF(ISNUMBER(FIND(MID($L7,26,1),"0123456789")),MID($L7,26,1),IF(ISNUMBER(FIND(MID($L7,26,1),"ABCDEFGHIJKLMNOPQRSTUVWXYZ")),CODE(MID($L7,26,1))-55,"#"))) | AN7: =IF(LEN($L7)<27,"",IF(ISNUMBER(FIND(MID($L7,27,1),"0123456789")),MID($L7,27,1),IF(ISNUMBER(FIND(MID($L7,27,1),"ABCDEFGHIJKLMNOPQRSTUVWXYZ")),CODE(MID($L7,27,1))-55,"#"))) | AO7: =IF(LEN($L7)<28,"",IF(ISNUMBER(FIND(MID($L7,28,1),"0123456789")),MID($L7,28,1),IF(ISNUMBER(FIND(MID($L7,28,1),"ABCDEFGHIJKLMNOPQRSTUVWXYZ")),CODE(MID($L7,28,1))-55,"#"))) | AP7: =IF(LEN($L7)<29,"",IF(ISNUMBER(FIND(MID($L7,29,1),"0123456789")),MID($L7,29,1),IF(ISNUMBER(FIND(MID($L7,29,1),"ABCDEFGHIJKLMNOPQRSTUVWXYZ")),CODE(MID($L7,29,1))-55,"#"))) | AQ7: =IF(LEN($L7)<30,"",IF(ISNUMBER(FIND(MID($L7,30,1),"0123456789")),MID($L7,30,1),IF(ISNUMBER(FIND(MID($L7,30,1),"ABCDEFGHIJKLMNOPQRSTUVWXYZ")),CODE(MID($L7,30,1))-55,"#"))) | AR7: =IF(LEN($L7)<31,"",IF(ISNUMBER(FIND(MID($L7,31,1),"0123456789")),MID($L7,31,1),IF(ISNUMBER(FIND(MID($L7,31,1),"ABCDEFGHIJKLMNOPQRSTUVWXYZ")),CODE(MID($L7,31,1))-55,"#"))) | AS7: =IF(LEN($L7)<32,"",IF(ISNUMBER(FIND(MID($L7,32,1),"0123456789")),MID($L7,32,1),IF(ISNUMBER(FIND(MID($L7,32,1),"ABCDEFGHIJKLMNOPQRSTUVWXYZ")),CODE(MID($L7,32,1))-55,"#"))) | AT7: =IF(LEN($L7)<33,"",IF(ISNUMBER(FIND(MID($L7,33,1),"0123456789")),MID($L7,33,1),IF(ISNUMBER(FIND(MID($L7,33,1),"ABCDEFGHIJKLMNOPQRSTUVWXYZ")),CODE(MID($L7,33,1))-55,"#"))) | AU7: =IF(LEN($L7)<34,"",IF(ISNUMBER(FIND(MID($L7,34,1),"0123456789")),MID($L7,34,1),IF(ISNUMBER(FIND(MID($L7,34,1),"ABCDEFGHIJKLMNOPQRSTUVWXYZ")),CODE(MID($L7,34,1))-55,"#"))) | AV7: =_xlfn.CONCAT(N7:AU7) -> 80000000608010167591281003 | AW7: =IF(OR(AV7="",M7=FALSE()),"",MOD(VALUE(MID(AV7,1,9)),97)) -> 72 | AX7: =IF(AW7="","",MOD(VALUE(AW7&MID(AV7,10,7)),97)) -> 30 | AY7: =IF(AX7="","",MOD(VALUE(AX7&MID(AV7,17,7)),97)) -> 13 | AZ7: =IF(AY7="","",MOD(VALUE(AY7&MID(AV7,24,7)),97)) -> 5 | BA7: =IF(AZ7="","",MOD(VALUE(AZ7&MID(AV7,31,7)),97)) -> 5 | BB7: =IF(BA7="","",MOD(VALUE(BA7&MID(AV7,38,7)),97)) -> 5 | BC7: =IF(BB7="","",MOD(VALUE(BB7&MID(AV7,45,7)),97)) -> 5 | BD7: =IF(BC7="","",MOD(VALUE(BC7&MID(AV7,52,7)),97)) -> 5 | BE7: =IF(BD7="","",MOD(VALUE(BD7&MID(AV7,59,7)),97)) -> 5 | BF7: =IF(BE7="","",MOD(VALUE(BE7&MID(AV7,66,7)),97)) -> 5
A8: SA44 2000 0001 2345 6789 1234 | B8: =UPPER(SUBSTITUTE(SUBSTITUTE(SUBSTITUTE(TRIM(A8)," ",""),"-",""),CHAR(160),"")) -> SA4420000001234567891234 | C8: =IF(B8="","",LEN(B8)) -> 24 | D8: =IF(B8="","",LEFT(B8,2)) -> SA | E8: =IF(B8="","",MID(B8,3,2)) -> 44 | F8: =IF(B8="","",MID(B8,5,2)) -> 20 | G8: =IF(B8="","",IFERROR(INDEX('رموز البنوك'!$C$5:$C$30,MATCH(F8,'رموز البنوك'!$B$5:$B$30,0)),"رمز غير معروف")) -> بنك الرياض | H8: =BF8 -> 1 | I8: =IF(OR(H8="",NOT(AND(ISNUMBER(FIND(MID(B8,3,1),"0123456789")),ISNUMBER(FIND(MID(B8,4,1),"0123456789"))))),"",TEXT(98-MOD(H8-VALUE(E8),97),"00")) -> 44 | J8: =IF(B8="","",IF(LEFT(K8,10)="آيبان صحيح","صحيح ✓","غير صحيح ✗")) -> صحيح ✓ | K8: =IF(B8="","",IF(M8=FALSE(),"يحتوي رموزاً غير مسموحة (المسموح A–Z و 0–9 فقط)",IF(D8<>"SA","رمز الدولة "&D8&" — هذا المدقق للآيبان السعودي SA",IF(C8<>24,"الطول "&C8&" خانة والمطلوب 24",IF(NOT(AND(ISNUMBER(FIND(MID(B8,3,1),"0123456789")),ISNUMBER(FIND(MID(B8,4,1),"0123456789")))),"خانتا التدقيق يجب أن تكونا رقمين",IF(ISERROR(VALUE(MID(B8,5,20))),"رمز البنك ورقم الحساب يجب أن يكونا أرقاماً",IF(H8<>1,"فشل اختبار MOD-97 (الباقي "&H8&" وليس 1) — خطأ في كتابة الرقم؛ خانتا التدقيق الصحيحتان لهذا الحساب "&I8,IF(G8="رمز غير معروف","اجتاز MOD-97 لكن رمز البنك "&F8&" غير مسجل في جدول البنوك","آيبان صحيح — "&G8)))))))) -> آيبان صحيح — بنك الرياض | L8: =IF(B8="","",MID(B8,5,40)&LEFT(B8,4)) -> 20000001234567891234SA44 | M8: =IF(L8="","",NOT(ISNUMBER(FIND("#",AV8)))) -> TRUE | N8: =IF(LEN($L8)<1,"",IF(ISNUMBER(FIND(MID($L8,1,1),"0123456789")),MID($L8,1,1),IF(ISNUMBER(FIND(MID($L8,1,1),"ABCDEFGHIJKLMNOPQRSTUVWXYZ")),CODE(MID($L8,1,1))-55,"#"))) -> 2 | O8: =IF(LEN($L8)<2,"",IF(ISNUMBER(FIND(MID($L8,2,1),"0123456789")),MID($L8,2,1),IF(ISNUMBER(FIND(MID($L8,2,1),"ABCDEFGHIJKLMNOPQRSTUVWXYZ")),CODE(MID($L8,2,1))-55,"#"))) -> 0 | P8: =IF(LEN($L8)<3,"",IF(ISNUMBER(FIND(MID($L8,3,1),"0123456789")),MID($L8,3,1),IF(ISNUMBER(FIND(MID($L8,3,1),"ABCDEFGHIJKLMNOPQRSTUVWXYZ")),CODE(MID($L8,3,1))-55,"#"))) -> 0 | Q8: =IF(LEN($L8)<4,"",IF(ISNUMBER(FIND(MID($L8,4,1),"0123456789")),MID($L8,4,1),IF(ISNUMBER(FIND(MID($L8,4,1),"ABCDEFGHIJKLMNOPQRSTUVWXYZ")),CODE(MID($L8,4,1))-55,"#"))) -> 0 | R8: =IF(LEN($L8)<5,"",IF(ISNUMBER(FIND(MID($L8,5,1),"0123456789")),MID($L8,5,1),IF(ISNUMBER(FIND(MID($L8,5,1),"ABCDEFGHIJKLMNOPQRSTUVWXYZ")),CODE(MID($L8,5,1))-55,"#"))) -> 0 | S8: =IF(LEN($L8)<6,"",IF(ISNUMBER(FIND(MID($L8,6,1),"0123456789")),MID($L8,6,1),IF(ISNUMBER(FIND(MID($L8,6,1),"ABCDEFGHIJKLMNOPQRSTUVWXYZ")),CODE(MID($L8,6,1))-55,"#"))) -> 0 | T8: =IF(LEN($L8)<7,"",IF(ISNUMBER(FIND(MID($L8,7,1),"0123456789")),MID($L8,7,1),IF(ISNUMBER(FIND(MID($L8,7,1),"ABCDEFGHIJKLMNOPQRSTUVWXYZ")),CODE(MID($L8,7,1))-55,"#"))) -> 0 | U8: =IF(LEN($L8)<8,"",IF(ISNUMBER(FIND(MID($L8,8,1),"0123456789")),MID($L8,8,1),IF(ISNUMBER(FIND(MID($L8,8,1),"ABCDEFGHIJKLMNOPQRSTUVWXYZ")),CODE(MID($L8,8,1))-55,"#"))) -> 1 | V8: =IF(LEN($L8)<9,"",IF(ISNUMBER(FIND(MID($L8,9,1),"0123456789")),MID($L8,9,1),IF(ISNUMBER(FIND(MID($L8,9,1),"ABCDEFGHIJKLMNOPQRSTUVWXYZ")),CODE(MID($L8,9,1))-55,"#"))) -> 2 | W8: =IF(LEN($L8)<10,"",IF(ISNUMBER(FIND(MID($L8,10,1),"0123456789")),MID($L8,10,1),IF(ISNUMBER(FIND(MID($L8,10,1),"ABCDEFGHIJKLMNOPQRSTUVWXYZ")),CODE(MID($L8,10,1))-55,"#"))) -> 3 | X8: =IF(LEN($L8)<11,"",IF(ISNUMBER(FIND(MID($L8,11,1),"0123456789")),MID($L8,11,1),IF(ISNUMBER(FIND(MID($L8,11,1),"ABCDEFGHIJKLMNOPQRSTUVWXYZ")),CODE(MID($L8,11,1))-55,"#"))) -> 4 | Y8: =IF(LEN($L8)<12,"",IF(ISNUMBER(FIND(MID($L8,12,1),"0123456789")),MID($L8,12,1),IF(ISNUMBER(FIND(MID($L8,12,1),"ABCDEFGHIJKLMNOPQRSTUVWXYZ")),CODE(MID($L8,12,1))-55,"#"))) -> 5 | Z8: =IF(LEN($L8)<13,"",IF(ISNUMBER(FIND(MID($L8,13,1),"0123456789")),MID($L8,13,1),IF(ISNUMBER(FIND(MID($L8,13,1),"ABCDEFGHIJKLMNOPQRSTUVWXYZ")),CODE(MID($L8,13,1))-55,"#"))) -> 6 | AA8: =IF(LEN($L8)<14,"",IF(ISNUMBER(FIND(MID($L8,14,1),"0123456789")),MID($L8,14,1),IF(ISNUMBER(FIND(MID($L8,14,1),"ABCDEFGHIJKLMNOPQRSTUVWXYZ")),CODE(MID($L8,14,1))-55,"#"))) -> 7 | AB8: =IF(LEN($L8)<15,"",IF(ISNUMBER(FIND(MID($L8,15,1),"0123456789")),MID($L8,15,1),IF(ISNUMBER(FIND(MID($L8,15,1),"ABCDEFGHIJKLMNOPQRSTUVWXYZ")),CODE(MID($L8,15,1))-55,"#"))) -> 8 | AC8: =IF(LEN($L8)<16,"",IF(ISNUMBER(FIND(MID($L8,16,1),"0123456789")),MID($L8,16,1),IF(ISNUMBER(FIND(MID($L8,16,1),"ABCDEFGHIJKLMNOPQRSTUVWXYZ")),CODE(MID($L8,16,1))-55,"#"))) -> 9 | AD8: =IF(LEN($L8)<17,"",IF(ISNUMBER(FIND(MID($L8,17,1),"0123456789")),MID($L8,17,1),IF(ISNUMBER(FIND(MID($L8,17,1),"ABCDEFGHIJKLMNOPQRSTUVWXYZ")),CODE(MID($L8,17,1))-55,"#"))) -> 1 | AE8: =IF(LEN($L8)<18,"",IF(ISNUMBER(FIND(MID($L8,18,1),"0123456789")),MID($L8,18,1),IF(ISNUMBER(FIND(MID($L8,18,1),"ABCDEFGHIJKLMNOPQRSTUVWXYZ")),CODE(MID($L8,18,1))-55,"#"))) -> 2 | AF8: =IF(LEN($L8)<19,"",IF(ISNUMBER(FIND(MID($L8,19,1),"0123456789")),MID($L8,19,1),IF(ISNUMBER(FIND(MID($L8,19,1),"ABCDEFGHIJKLMNOPQRSTUVWXYZ")),CODE(MID($L8,19,1))-55,"#"))) -> 3 | AG8: =IF(LEN($L8)<20,"",IF(ISNUMBER(FIND(MID($L8,20,1),"0123456789")),MID($L8,20,1),IF(ISNUMBER(FIND(MID($L8,20,1),"ABCDEFGHIJKLMNOPQRSTUVWXYZ")),CODE(MID($L8,20,1))-55,"#"))) -> 4 | AH8: =IF(LEN($L8)<21,"",IF(ISNUMBER(FIND(MID($L8,21,1),"0123456789")),MID($L8,21,1),IF(ISNUMBER(FIND(MID($L8,21,1),"ABCDEFGHIJKLMNOPQRSTUVWXYZ")),CODE(MID($L8,21,1))-55,"#"))) -> 28 | AI8: =IF(LEN($L8)<22,"",IF(ISNUMBER(FIND(MID($L8,22,1),"0123456789")),MID($L8,22,1),IF(ISNUMBER(FIND(MID($L8,22,1),"ABCDEFGHIJKLMNOPQRSTUVWXYZ")),CODE(MID($L8,22,1))-55,"#"))) -> 10 | AJ8: =IF(LEN($L8)<23,"",IF(ISNUMBER(FIND(MID($L8,23,1),"0123456789")),MID($L8,23,1),IF(ISNUMBER(FIND(MID($L8,23,1),"ABCDEFGHIJKLMNOPQRSTUVWXYZ")),CODE(MID($L8,23,1))-55,"#"))) -> 4 | AK8: =IF(LEN($L8)<24,"",IF(ISNUMBER(FIND(MID($L8,24,1),"0123456789")),MID($L8,24,1),IF(ISNUMBER(FIND(MID($L8,24,1),"ABCDEFGHIJKLMNOPQRSTUVWXYZ")),CODE(MID($L8,24,1))-55,"#"))) -> 4 | AL8: =IF(LEN($L8)<25,"",IF(ISNUMBER(FIND(MID($L8,25,1),"0123456789")),MID($L8,25,1),IF(ISNUMBER(FIND(MID($L8,25,1),"ABCDEFGHIJKLMNOPQRSTUVWXYZ")),CODE(MID($L8,25,1))-55,"#"))) | AM8: =IF(LEN($L8)<26,"",IF(ISNUMBER(FIND(MID($L8,26,1),"0123456789")),MID($L8,26,1),IF(ISNUMBER(FIND(MID($L8,26,1),"ABCDEFGHIJKLMNOPQRSTUVWXYZ")),CODE(MID($L8,26,1))-55,"#"))) | AN8: =IF(LEN($L8)<27,"",IF(ISNUMBER(FIND(MID($L8,27,1),"0123456789")),MID($L8,27,1),IF(ISNUMBER(FIND(MID($L8,27,1),"ABCDEFGHIJKLMNOPQRSTUVWXYZ")),CODE(MID($L8,27,1))-55,"#"))) | AO8: =IF(LEN($L8)<28,"",IF(ISNUMBER(FIND(MID($L8,28,1),"0123456789")),MID($L8,28,1),IF(ISNUMBER(FIND(MID($L8,28,1),"ABCDEFGHIJKLMNOPQRSTUVWXYZ")),CODE(MID($L8,28,1))-55,"#"))) | AP8: =IF(LEN($L8)<29,"",IF(ISNUMBER(FIND(MID($L8,29,1),"0123456789")),MID($L8,29,1),IF(ISNUMBER(FIND(MID($L8,29,1),"ABCDEFGHIJKLMNOPQRSTUVWXYZ")),CODE(MID($L8,29,1))-55,"#"))) | AQ8: =IF(LEN($L8)<30,"",IF(ISNUMBER(FIND(MID($L8,30,1),"0123456789")),MID($L8,30,1),IF(ISNUMBER(FIND(MID($L8,30,1),"ABCDEFGHIJKLMNOPQRSTUVWXYZ")),CODE(MID($L8,30,1))-55,"#"))) | AR8: =IF(LEN($L8)<31,"",IF(ISNUMBER(FIND(MID($L8,31,1),"0123456789")),MID($L8,31,1),IF(ISNUMBER(FIND(MID($L8,31,1),"ABCDEFGHIJKLMNOPQRSTUVWXYZ")),CODE(MID($L8,31,1))-55,"#"))) | AS8: =IF(LEN($L8)<32,"",IF(ISNUMBER(FIND(MID($L8,32,1),"0123456789")),MID($L8,32,1),IF(ISNUMBER(FIND(MID($L8,32,1),"ABCDEFGHIJKLMNOPQRSTUVWXYZ")),CODE(MID($L8,32,1))-55,"#"))) | AT8: =IF(LEN($L8)<33,"",IF(ISNUMBER(FIND(MID($L8,33,1),"0123456789")),MID($L8,33,1),IF(ISNUMBER(FIND(MID($L8,33,1),"ABCDEFGHIJKLMNOPQRSTUVWXYZ")),CODE(MID($L8,33,1))-55,"#"))) | AU8: =IF(LEN($L8)<34,"",IF(ISNUMBER(FIND(MID($L8,34,1),"0123456789")),MID($L8,34,1),IF(ISNUMBER(FIND(MID($L8,34,1),"ABCDEFGHIJKLMNOPQRSTUVWXYZ")),CODE(MID($L8,34,1))-55,"#"))) | AV8: =_xlfn.CONCAT(N8:AU8) -> 20000001234567891234281044 | AW8: =IF(OR(AV8="",M8=FALSE()),"",MOD(VALUE(MID(AV8,1,9)),97)) -> 77 | AX8: =IF(AW8="","",MOD(VALUE(AW8&MID(AV8,10,7)),97)) -> 32 | AY8: =IF(AX8="","",MOD(VALUE(AX8&MID(AV8,17,7)),97)) -> 60 | AZ8: =IF(AY8="","",MOD(VALUE(AY8&MID(AV8,24,7)),97)) -> 1 | BA8: =IF(AZ8="","",MOD(VALUE(AZ8&MID(AV8,31,7)),97)) -> 1 | BB8: =IF(BA8="","",MOD(VALUE(BA8&MID(AV8,38,7)),97)) -> 1 | BC8: =IF(BB8="","",MOD(VALUE(BB8&MID(AV8,45,7)),97)) -> 1 | BD8: =IF(BC8="","",MOD(VALUE(BC8&MID(AV8,52,7)),97)) -> 1 | BE8: =IF(BD8="","",MOD(VALUE(BD8&MID(AV8,59,7)),97)) -> 1 | BF8: =IF(BE8="","",MOD(VALUE(BE8&MID(AV8,66,7)),97)) -> 1
